2024-01-24 19:51:54,651 - ERROR - Error in operation: 'NoneType' object is not subscriptable
Traceback (most recent call last):
  File "/home/userdm/code/geekhub-homework/HT_20/main/views.py", line 103, in add_products
    future.result()
  File "/home/userdm/.pyenv/versions/3.11.0/lib/python3.11/concurrent/futures/_base.py", line 449, in result
    return self.__get_result()
           ^^^^^^^^^^^^^^^^^^^
  File "/home/userdm/.pyenv/versions/3.11.0/lib/python3.11/concurrent/futures/_base.py", line 401, in __get_result
    raise self._exception
  File "/home/userdm/.pyenv/versions/3.11.0/lib/python3.11/concurrent/futures/thread.py", line 58, in run
    result = self.fn(*self.args, **self.kwargs)
             ^^^^^^^^^^^^^^^^^^^^^^^^^^^^^^^^^^
  File "/home/userdm/code/geekhub-homework/HT_20/main/views.py", line 129, in parse_and_save_product
    data = scraper.get_product_informations()
           ^^^^^^^^^^^^^^^^^^^^^^^^^^^^^^^^^^
  File "/home/userdm/code/geekhub-homework/HT_20/utils/parser.py", line 127, in get_product_informations
    'seller': data['productDetail']['softhardProductdetails'][0]['defaultSeller']['soldBy'] or 'None',
              ~~~~~~~~~~~~~~~~~~~~~~~~~~~~~~~~~~~~~~~~~~~~~~~~~~~~~~~~~~~~~~~~~~~^^^^^^^^^^
TypeError: 'NoneType' object is not subscriptable
Internal Server Error: /api/v1/productlist/
Traceback (most recent call last):
  File "/home/userdm/code/env_pool/env_gh_ht21/lib/python3.11/site-packages/django/core/handlers/exception.py", line 55, in inner
    response = get_response(request)
               ^^^^^^^^^^^^^^^^^^^^^
  File "/home/userdm/code/env_pool/env_gh_ht21/lib/python3.11/site-packages/django/core/handlers/base.py", line 197, in _get_response
    response = wrapped_callback(request, *callback_args, **callback_kwargs)
               ^^^^^^^^^^^^^^^^^^^^^^^^^^^^^^^^^^^^^^^^^^^^^^^^^^^^^^^^^^^^
  File "/home/userdm/code/env_pool/env_gh_ht21/lib/python3.11/site-packages/django/views/decorators/csrf.py", line 65, in _view_wrapper
    return view_func(request, *args, **kwargs)
           ^^^^^^^^^^^^^^^^^^^^^^^^^^^^^^^^^^^
  File "/home/userdm/code/env_pool/env_gh_ht21/lib/python3.11/site-packages/django/views/generic/base.py", line 104, in view
    return self.dispatch(request, *args, **kwargs)
           ^^^^^^^^^^^^^^^^^^^^^^^^^^^^^^^^^^^^^^^
  File "/home/userdm/code/env_pool/env_gh_ht21/lib/python3.11/site-packages/rest_framework/views.py", line 509, in dispatch
    response = self.handle_exception(exc)
               ^^^^^^^^^^^^^^^^^^^^^^^^^^
  File "/home/userdm/code/env_pool/env_gh_ht21/lib/python3.11/site-packages/rest_framework/views.py", line 469, in handle_exception
    self.raise_uncaught_exception(exc)
  File "/home/userdm/code/env_pool/env_gh_ht21/lib/python3.11/site-packages/rest_framework/views.py", line 480, in raise_uncaught_exception
    raise exc
  File "/home/userdm/code/env_pool/env_gh_ht21/lib/python3.11/site-packages/rest_framework/views.py", line 506, in dispatch
    response = handler(request, *args, **kwargs)
               ^^^^^^^^^^^^^^^^^^^^^^^^^^^^^^^^^
  File "/home/userdm/code/env_pool/env_gh_ht21/lib/python3.11/site-packages/rest_framework/generics.py", line 239, in get
    return self.list(request, *args, **kwargs)
           ^^^^^^^^^^^^^^^^^^^^^^^^^^^^^^^^^^^
  File "/home/userdm/code/env_pool/env_gh_ht21/lib/python3.11/site-packages/rest_framework/mixins.py", line 46, in list
    return Response(serializer.data)
                    ^^^^^^^^^^^^^^^
  File "/home/userdm/code/env_pool/env_gh_ht21/lib/python3.11/site-packages/rest_framework/serializers.py", line 768, in data
    ret = super().data
          ^^^^^^^^^^^^
  File "/home/userdm/code/env_pool/env_gh_ht21/lib/python3.11/site-packages/rest_framework/serializers.py", line 253, in data
    self._data = self.to_representation(self.instance)
                 ^^^^^^^^^^^^^^^^^^^^^^^^^^^^^^^^^^^^^
  File "/home/userdm/code/env_pool/env_gh_ht21/lib/python3.11/site-packages/rest_framework/serializers.py", line 686, in to_representation
    return [
           ^
  File "/home/userdm/code/env_pool/env_gh_ht21/lib/python3.11/site-packages/rest_framework/serializers.py", line 687, in <listcomp>
    self.child.to_representation(item) for item in iterable
    ^^^^^^^^^^^^^^^^^^^^^^^^^^^^^^^^^^
  File "/home/userdm/code/env_pool/env_gh_ht21/lib/python3.11/site-packages/rest_framework/serializers.py", line 507, in to_representation
    for field in fields:
  File "/home/userdm/code/env_pool/env_gh_ht21/lib/python3.11/site-packages/rest_framework/serializers.py", line 368, in _readable_fields
    for field in self.fields.values():
                 ^^^^^^^^^^^
  File "/home/userdm/code/env_pool/env_gh_ht21/lib/python3.11/site-packages/django/utils/functional.py", line 47, in __get__
    res = instance.__dict__[self.name] = self.func(instance)
                                         ^^^^^^^^^^^^^^^^^^^
  File "/home/userdm/code/env_pool/env_gh_ht21/lib/python3.11/site-packages/rest_framework/serializers.py", line 356, in fields
    for key, value in self.get_fields().items():
                      ^^^^^^^^^^^^^^^^^
  File "/home/userdm/code/env_pool/env_gh_ht21/lib/python3.11/site-packages/rest_framework/serializers.py", line 1032, in get_fields
    assert hasattr(self.Meta, 'model'), (
AssertionError: Class ProductSerializer missing "Meta.model" attribute
"GET /api/v1/productlist/ HTTP/1.1" 500 139473
Internal Server Error: /api/v1/cartlist/
Traceback (most recent call last):
  File "/home/userdm/code/env_pool/env_gh_ht21/lib/python3.11/site-packages/django/core/handlers/exception.py", line 55, in inner
    response = get_response(request)
               ^^^^^^^^^^^^^^^^^^^^^
  File "/home/userdm/code/env_pool/env_gh_ht21/lib/python3.11/site-packages/django/core/handlers/base.py", line 197, in _get_response
    response = wrapped_callback(request, *callback_args, **callback_kwargs)
               ^^^^^^^^^^^^^^^^^^^^^^^^^^^^^^^^^^^^^^^^^^^^^^^^^^^^^^^^^^^^
  File "/home/userdm/code/env_pool/env_gh_ht21/lib/python3.11/site-packages/django/views/decorators/csrf.py", line 65, in _view_wrapper
    return view_func(request, *args, **kwargs)
           ^^^^^^^^^^^^^^^^^^^^^^^^^^^^^^^^^^^
  File "/home/userdm/code/env_pool/env_gh_ht21/lib/python3.11/site-packages/django/views/generic/base.py", line 104, in view
    return self.dispatch(request, *args, **kwargs)
           ^^^^^^^^^^^^^^^^^^^^^^^^^^^^^^^^^^^^^^^
  File "/home/userdm/code/env_pool/env_gh_ht21/lib/python3.11/site-packages/rest_framework/views.py", line 509, in dispatch
    response = self.handle_exception(exc)
               ^^^^^^^^^^^^^^^^^^^^^^^^^^
  File "/home/userdm/code/env_pool/env_gh_ht21/lib/python3.11/site-packages/rest_framework/views.py", line 469, in handle_exception
    self.raise_uncaught_exception(exc)
  File "/home/userdm/code/env_pool/env_gh_ht21/lib/python3.11/site-packages/rest_framework/views.py", line 480, in raise_uncaught_exception
    raise exc
  File "/home/userdm/code/env_pool/env_gh_ht21/lib/python3.11/site-packages/rest_framework/views.py", line 506, in dispatch
    response = handler(request, *args, **kwargs)
               ^^^^^^^^^^^^^^^^^^^^^^^^^^^^^^^^^
  File "/home/userdm/code/python-course/gh-hometask/HT_21/api/views.py", line 35, in get
    print(request.session.get['cart_list'])
          ~~~~~~~~~~~~~~~~~~~^^^^^^^^^^^^^
TypeError: 'method' object is not subscriptable
"GET /api/v1/cartlist/ HTTP/1.1" 500 93480
Internal Server Error: /api/v1/cartlist/
Traceback (most recent call last):
  File "/home/userdm/code/env_pool/env_gh_ht21/lib/python3.11/site-packages/django/core/handlers/exception.py", line 55, in inner
    response = get_response(request)
               ^^^^^^^^^^^^^^^^^^^^^
  File "/home/userdm/code/env_pool/env_gh_ht21/lib/python3.11/site-packages/django/core/handlers/base.py", line 197, in _get_response
    response = wrapped_callback(request, *callback_args, **callback_kwargs)
               ^^^^^^^^^^^^^^^^^^^^^^^^^^^^^^^^^^^^^^^^^^^^^^^^^^^^^^^^^^^^
  File "/home/userdm/code/env_pool/env_gh_ht21/lib/python3.11/site-packages/django/views/decorators/csrf.py", line 65, in _view_wrapper
    return view_func(request, *args, **kwargs)
           ^^^^^^^^^^^^^^^^^^^^^^^^^^^^^^^^^^^
  File "/home/userdm/code/env_pool/env_gh_ht21/lib/python3.11/site-packages/django/views/generic/base.py", line 104, in view
    return self.dispatch(request, *args, **kwargs)
           ^^^^^^^^^^^^^^^^^^^^^^^^^^^^^^^^^^^^^^^
  File "/home/userdm/code/env_pool/env_gh_ht21/lib/python3.11/site-packages/rest_framework/views.py", line 509, in dispatch
    response = self.handle_exception(exc)
               ^^^^^^^^^^^^^^^^^^^^^^^^^^
  File "/home/userdm/code/env_pool/env_gh_ht21/lib/python3.11/site-packages/rest_framework/views.py", line 469, in handle_exception
    self.raise_uncaught_exception(exc)
  File "/home/userdm/code/env_pool/env_gh_ht21/lib/python3.11/site-packages/rest_framework/views.py", line 480, in raise_uncaught_exception
    raise exc
  File "/home/userdm/code/env_pool/env_gh_ht21/lib/python3.11/site-packages/rest_framework/views.py", line 506, in dispatch
    response = handler(request, *args, **kwargs)
               ^^^^^^^^^^^^^^^^^^^^^^^^^^^^^^^^^
  File "/home/userdm/code/python-course/gh-hometask/HT_21/api/views.py", line 35, in get
    print(request.session['cart_list'])
          ~~~~~~~~~~~~~~~^^^^^^^^^^^^^
  File "/home/userdm/code/env_pool/env_gh_ht21/lib/python3.11/site-packages/django/contrib/sessions/backends/base.py", line 53, in __getitem__
    return self._session[key]
           ~~~~~~~~~~~~~^^^^^
KeyError: 'cart_list'
"GET /api/v1/cartlist/ HTTP/1.1" 500 97165
Internal Server Error: /api/v1/cartlist/
Traceback (most recent call last):
  File "/home/userdm/code/env_pool/env_gh_ht21/lib/python3.11/site-packages/django/core/handlers/exception.py", line 55, in inner
    response = get_response(request)
               ^^^^^^^^^^^^^^^^^^^^^
  File "/home/userdm/code/env_pool/env_gh_ht21/lib/python3.11/site-packages/django/core/handlers/base.py", line 197, in _get_response
    response = wrapped_callback(request, *callback_args, **callback_kwargs)
               ^^^^^^^^^^^^^^^^^^^^^^^^^^^^^^^^^^^^^^^^^^^^^^^^^^^^^^^^^^^^
  File "/home/userdm/code/env_pool/env_gh_ht21/lib/python3.11/site-packages/django/views/decorators/csrf.py", line 65, in _view_wrapper
    return view_func(request, *args, **kwargs)
           ^^^^^^^^^^^^^^^^^^^^^^^^^^^^^^^^^^^
  File "/home/userdm/code/env_pool/env_gh_ht21/lib/python3.11/site-packages/django/views/generic/base.py", line 104, in view
    return self.dispatch(request, *args, **kwargs)
           ^^^^^^^^^^^^^^^^^^^^^^^^^^^^^^^^^^^^^^^
  File "/home/userdm/code/env_pool/env_gh_ht21/lib/python3.11/site-packages/rest_framework/views.py", line 509, in dispatch
    response = self.handle_exception(exc)
               ^^^^^^^^^^^^^^^^^^^^^^^^^^
  File "/home/userdm/code/env_pool/env_gh_ht21/lib/python3.11/site-packages/rest_framework/views.py", line 469, in handle_exception
    self.raise_uncaught_exception(exc)
  File "/home/userdm/code/env_pool/env_gh_ht21/lib/python3.11/site-packages/rest_framework/views.py", line 480, in raise_uncaught_exception
    raise exc
  File "/home/userdm/code/env_pool/env_gh_ht21/lib/python3.11/site-packages/rest_framework/views.py", line 506, in dispatch
    response = handler(request, *args, **kwargs)
               ^^^^^^^^^^^^^^^^^^^^^^^^^^^^^^^^^
  File "/home/userdm/code/python-course/gh-hometask/HT_21/api/views.py", line 36, in get
    print(request.session.key())
          ^^^^^^^^^^^^^^^^^^^
AttributeError: 'SessionStore' object has no attribute 'key'
"GET /api/v1/cartlist/ HTTP/1.1" 500 93419
Internal Server Error: /api/v1/cartlist/
Traceback (most recent call last):
  File "/home/userdm/code/env_pool/env_gh_ht21/lib/python3.11/site-packages/django/core/handlers/exception.py", line 55, in inner
    response = get_response(request)
               ^^^^^^^^^^^^^^^^^^^^^
  File "/home/userdm/code/env_pool/env_gh_ht21/lib/python3.11/site-packages/django/core/handlers/base.py", line 197, in _get_response
    response = wrapped_callback(request, *callback_args, **callback_kwargs)
               ^^^^^^^^^^^^^^^^^^^^^^^^^^^^^^^^^^^^^^^^^^^^^^^^^^^^^^^^^^^^
  File "/home/userdm/code/env_pool/env_gh_ht21/lib/python3.11/site-packages/django/views/decorators/csrf.py", line 65, in _view_wrapper
    return view_func(request, *args, **kwargs)
           ^^^^^^^^^^^^^^^^^^^^^^^^^^^^^^^^^^^
  File "/home/userdm/code/env_pool/env_gh_ht21/lib/python3.11/site-packages/django/views/generic/base.py", line 104, in view
    return self.dispatch(request, *args, **kwargs)
           ^^^^^^^^^^^^^^^^^^^^^^^^^^^^^^^^^^^^^^^
  File "/home/userdm/code/env_pool/env_gh_ht21/lib/python3.11/site-packages/rest_framework/views.py", line 509, in dispatch
    response = self.handle_exception(exc)
               ^^^^^^^^^^^^^^^^^^^^^^^^^^
  File "/home/userdm/code/env_pool/env_gh_ht21/lib/python3.11/site-packages/rest_framework/views.py", line 469, in handle_exception
    self.raise_uncaught_exception(exc)
  File "/home/userdm/code/env_pool/env_gh_ht21/lib/python3.11/site-packages/rest_framework/views.py", line 480, in raise_uncaught_exception
    raise exc
  File "/home/userdm/code/env_pool/env_gh_ht21/lib/python3.11/site-packages/rest_framework/views.py", line 506, in dispatch
    response = handler(request, *args, **kwargs)
               ^^^^^^^^^^^^^^^^^^^^^^^^^^^^^^^^^
  File "/home/userdm/code/python-course/gh-hometask/HT_21/api/views.py", line 34, in get
    cart_data = request.session.get('product_data', []).get('cart_list', [])
                ^^^^^^^^^^^^^^^^^^^^^^^^^^^^^^^^^^^^^^^^^^^
AttributeError: 'list' object has no attribute 'get'
"GET /api/v1/cartlist/ HTTP/1.1" 500 90810
Internal Server Error: /api/v1/cartlist/
Traceback (most recent call last):
  File "/home/userdm/code/env_pool/env_gh_ht21/lib/python3.11/site-packages/django/core/handlers/exception.py", line 55, in inner
    response = get_response(request)
               ^^^^^^^^^^^^^^^^^^^^^
  File "/home/userdm/code/env_pool/env_gh_ht21/lib/python3.11/site-packages/django/core/handlers/base.py", line 197, in _get_response
    response = wrapped_callback(request, *callback_args, **callback_kwargs)
               ^^^^^^^^^^^^^^^^^^^^^^^^^^^^^^^^^^^^^^^^^^^^^^^^^^^^^^^^^^^^
  File "/home/userdm/code/env_pool/env_gh_ht21/lib/python3.11/site-packages/django/views/decorators/csrf.py", line 65, in _view_wrapper
    return view_func(request, *args, **kwargs)
           ^^^^^^^^^^^^^^^^^^^^^^^^^^^^^^^^^^^
  File "/home/userdm/code/env_pool/env_gh_ht21/lib/python3.11/site-packages/django/views/generic/base.py", line 104, in view
    return self.dispatch(request, *args, **kwargs)
           ^^^^^^^^^^^^^^^^^^^^^^^^^^^^^^^^^^^^^^^
  File "/home/userdm/code/env_pool/env_gh_ht21/lib/python3.11/site-packages/rest_framework/views.py", line 509, in dispatch
    response = self.handle_exception(exc)
               ^^^^^^^^^^^^^^^^^^^^^^^^^^
  File "/home/userdm/code/env_pool/env_gh_ht21/lib/python3.11/site-packages/rest_framework/views.py", line 469, in handle_exception
    self.raise_uncaught_exception(exc)
  File "/home/userdm/code/env_pool/env_gh_ht21/lib/python3.11/site-packages/rest_framework/views.py", line 480, in raise_uncaught_exception
    raise exc
  File "/home/userdm/code/env_pool/env_gh_ht21/lib/python3.11/site-packages/rest_framework/views.py", line 506, in dispatch
    response = handler(request, *args, **kwargs)
               ^^^^^^^^^^^^^^^^^^^^^^^^^^^^^^^^^
  File "/home/userdm/code/python-course/gh-hometask/HT_21/api/views.py", line 34, in get
    cart_data = request.session.get('product_data', []).get('cart_list', [])
                ^^^^^^^^^^^^^^^^^^^^^^^^^^^^^^^^^^^^^^^^^^^
AttributeError: 'list' object has no attribute 'get'
"GET /api/v1/cartlist/ HTTP/1.1" 500 90810
Internal Server Error: /api/v1/cartlist/
Traceback (most recent call last):
  File "/home/userdm/code/env_pool/env_gh_ht21/lib/python3.11/site-packages/django/core/handlers/exception.py", line 55, in inner
    response = get_response(request)
               ^^^^^^^^^^^^^^^^^^^^^
  File "/home/userdm/code/env_pool/env_gh_ht21/lib/python3.11/site-packages/django/core/handlers/base.py", line 197, in _get_response
    response = wrapped_callback(request, *callback_args, **callback_kwargs)
               ^^^^^^^^^^^^^^^^^^^^^^^^^^^^^^^^^^^^^^^^^^^^^^^^^^^^^^^^^^^^
  File "/home/userdm/code/env_pool/env_gh_ht21/lib/python3.11/site-packages/django/views/decorators/csrf.py", line 65, in _view_wrapper
    return view_func(request, *args, **kwargs)
           ^^^^^^^^^^^^^^^^^^^^^^^^^^^^^^^^^^^
  File "/home/userdm/code/env_pool/env_gh_ht21/lib/python3.11/site-packages/django/views/generic/base.py", line 104, in view
    return self.dispatch(request, *args, **kwargs)
           ^^^^^^^^^^^^^^^^^^^^^^^^^^^^^^^^^^^^^^^
  File "/home/userdm/code/env_pool/env_gh_ht21/lib/python3.11/site-packages/rest_framework/views.py", line 509, in dispatch
    response = self.handle_exception(exc)
               ^^^^^^^^^^^^^^^^^^^^^^^^^^
  File "/home/userdm/code/env_pool/env_gh_ht21/lib/python3.11/site-packages/rest_framework/views.py", line 469, in handle_exception
    self.raise_uncaught_exception(exc)
  File "/home/userdm/code/env_pool/env_gh_ht21/lib/python3.11/site-packages/rest_framework/views.py", line 480, in raise_uncaught_exception
    raise exc
  File "/home/userdm/code/env_pool/env_gh_ht21/lib/python3.11/site-packages/rest_framework/views.py", line 506, in dispatch
    response = handler(request, *args, **kwargs)
               ^^^^^^^^^^^^^^^^^^^^^^^^^^^^^^^^^
  File "/home/userdm/code/python-course/gh-hometask/HT_21/api/views.py", line 34, in get
    cart_data = request.session.get('product_data', []).get('cart_list', [])
                ^^^^^^^^^^^^^^^^^^^^^^^^^^^^^^^^^^^^^^^^^^^
AttributeError: 'list' object has no attribute 'get'
"GET /api/v1/cartlist/ HTTP/1.1" 500 90810
Internal Server Error: /api/v1/cartlist/
Traceback (most recent call last):
  File "/home/userdm/code/env_pool/env_gh_ht21/lib/python3.11/site-packages/django/core/handlers/exception.py", line 55, in inner
    response = get_response(request)
               ^^^^^^^^^^^^^^^^^^^^^
  File "/home/userdm/code/env_pool/env_gh_ht21/lib/python3.11/site-packages/django/core/handlers/base.py", line 197, in _get_response
    response = wrapped_callback(request, *callback_args, **callback_kwargs)
               ^^^^^^^^^^^^^^^^^^^^^^^^^^^^^^^^^^^^^^^^^^^^^^^^^^^^^^^^^^^^
  File "/home/userdm/code/env_pool/env_gh_ht21/lib/python3.11/site-packages/django/views/decorators/csrf.py", line 65, in _view_wrapper
    return view_func(request, *args, **kwargs)
           ^^^^^^^^^^^^^^^^^^^^^^^^^^^^^^^^^^^
  File "/home/userdm/code/env_pool/env_gh_ht21/lib/python3.11/site-packages/django/views/generic/base.py", line 104, in view
    return self.dispatch(request, *args, **kwargs)
           ^^^^^^^^^^^^^^^^^^^^^^^^^^^^^^^^^^^^^^^
  File "/home/userdm/code/env_pool/env_gh_ht21/lib/python3.11/site-packages/rest_framework/views.py", line 509, in dispatch
    response = self.handle_exception(exc)
               ^^^^^^^^^^^^^^^^^^^^^^^^^^
  File "/home/userdm/code/env_pool/env_gh_ht21/lib/python3.11/site-packages/rest_framework/views.py", line 469, in handle_exception
    self.raise_uncaught_exception(exc)
  File "/home/userdm/code/env_pool/env_gh_ht21/lib/python3.11/site-packages/rest_framework/views.py", line 480, in raise_uncaught_exception
    raise exc
  File "/home/userdm/code/env_pool/env_gh_ht21/lib/python3.11/site-packages/rest_framework/views.py", line 506, in dispatch
    response = handler(request, *args, **kwargs)
               ^^^^^^^^^^^^^^^^^^^^^^^^^^^^^^^^^
  File "/home/userdm/code/python-course/gh-hometask/HT_21/api/views.py", line 34, in get
    cart_data = request.session.get('product_data', []).get('cart_list', [])
                ^^^^^^^^^^^^^^^^^^^^^^^^^^^^^^^^^^^^^^^^^^^
AttributeError: 'list' object has no attribute 'get'
"GET /api/v1/cartlist/ HTTP/1.1" 500 90810
Internal Server Error: /api/v1/cartlist/
Traceback (most recent call last):
  File "/home/userdm/code/env_pool/env_gh_ht21/lib/python3.11/site-packages/django/core/handlers/exception.py", line 55, in inner
    response = get_response(request)
               ^^^^^^^^^^^^^^^^^^^^^
  File "/home/userdm/code/env_pool/env_gh_ht21/lib/python3.11/site-packages/django/core/handlers/base.py", line 197, in _get_response
    response = wrapped_callback(request, *callback_args, **callback_kwargs)
               ^^^^^^^^^^^^^^^^^^^^^^^^^^^^^^^^^^^^^^^^^^^^^^^^^^^^^^^^^^^^
  File "/home/userdm/code/env_pool/env_gh_ht21/lib/python3.11/site-packages/django/views/decorators/csrf.py", line 65, in _view_wrapper
    return view_func(request, *args, **kwargs)
           ^^^^^^^^^^^^^^^^^^^^^^^^^^^^^^^^^^^
  File "/home/userdm/code/env_pool/env_gh_ht21/lib/python3.11/site-packages/django/views/generic/base.py", line 104, in view
    return self.dispatch(request, *args, **kwargs)
           ^^^^^^^^^^^^^^^^^^^^^^^^^^^^^^^^^^^^^^^
  File "/home/userdm/code/env_pool/env_gh_ht21/lib/python3.11/site-packages/rest_framework/views.py", line 509, in dispatch
    response = self.handle_exception(exc)
               ^^^^^^^^^^^^^^^^^^^^^^^^^^
  File "/home/userdm/code/env_pool/env_gh_ht21/lib/python3.11/site-packages/rest_framework/views.py", line 469, in handle_exception
    self.raise_uncaught_exception(exc)
  File "/home/userdm/code/env_pool/env_gh_ht21/lib/python3.11/site-packages/rest_framework/views.py", line 480, in raise_uncaught_exception
    raise exc
  File "/home/userdm/code/env_pool/env_gh_ht21/lib/python3.11/site-packages/rest_framework/views.py", line 506, in dispatch
    response = handler(request, *args, **kwargs)
               ^^^^^^^^^^^^^^^^^^^^^^^^^^^^^^^^^
  File "/home/userdm/code/python-course/gh-hometask/HT_21/api/views.py", line 34, in get
    cart_data = request.session.get('product_data', []).get('cart_list', [])
                ^^^^^^^^^^^^^^^^^^^^^^^^^^^^^^^^^^^^^^^^^^^
AttributeError: 'list' object has no attribute 'get'
"GET /api/v1/cartlist/ HTTP/1.1" 500 90801
Internal Server Error: /api/v1/cartlist/
Traceback (most recent call last):
  File "/home/userdm/code/env_pool/env_gh_ht21/lib/python3.11/site-packages/django/core/handlers/exception.py", line 55, in inner
    response = get_response(request)
               ^^^^^^^^^^^^^^^^^^^^^
  File "/home/userdm/code/env_pool/env_gh_ht21/lib/python3.11/site-packages/django/core/handlers/base.py", line 197, in _get_response
    response = wrapped_callback(request, *callback_args, **callback_kwargs)
               ^^^^^^^^^^^^^^^^^^^^^^^^^^^^^^^^^^^^^^^^^^^^^^^^^^^^^^^^^^^^
  File "/home/userdm/code/env_pool/env_gh_ht21/lib/python3.11/site-packages/django/views/decorators/csrf.py", line 65, in _view_wrapper
    return view_func(request, *args, **kwargs)
           ^^^^^^^^^^^^^^^^^^^^^^^^^^^^^^^^^^^
  File "/home/userdm/code/env_pool/env_gh_ht21/lib/python3.11/site-packages/django/views/generic/base.py", line 104, in view
    return self.dispatch(request, *args, **kwargs)
           ^^^^^^^^^^^^^^^^^^^^^^^^^^^^^^^^^^^^^^^
  File "/home/userdm/code/env_pool/env_gh_ht21/lib/python3.11/site-packages/rest_framework/views.py", line 509, in dispatch
    response = self.handle_exception(exc)
               ^^^^^^^^^^^^^^^^^^^^^^^^^^
  File "/home/userdm/code/env_pool/env_gh_ht21/lib/python3.11/site-packages/rest_framework/views.py", line 469, in handle_exception
    self.raise_uncaught_exception(exc)
  File "/home/userdm/code/env_pool/env_gh_ht21/lib/python3.11/site-packages/rest_framework/views.py", line 480, in raise_uncaught_exception
    raise exc
  File "/home/userdm/code/env_pool/env_gh_ht21/lib/python3.11/site-packages/rest_framework/views.py", line 506, in dispatch
    response = handler(request, *args, **kwargs)
               ^^^^^^^^^^^^^^^^^^^^^^^^^^^^^^^^^
  File "/home/userdm/code/python-course/gh-hometask/HT_21/api/views.py", line 34, in get
    cart_data = request.session.get('product_data', []).get('cart_list', [])
                ^^^^^^^^^^^^^^^^^^^^^^^^^^^^^^^^^^^^^^^^^^^
AttributeError: 'list' object has no attribute 'get'
"GET /api/v1/cartlist/ HTTP/1.1" 500 90801
Internal Server Error: /api/v1/cartlist/
Traceback (most recent call last):
  File "/home/userdm/code/env_pool/env_gh_ht21/lib/python3.11/site-packages/django/core/handlers/exception.py", line 55, in inner
    response = get_response(request)
               ^^^^^^^^^^^^^^^^^^^^^
  File "/home/userdm/code/env_pool/env_gh_ht21/lib/python3.11/site-packages/django/core/handlers/base.py", line 197, in _get_response
    response = wrapped_callback(request, *callback_args, **callback_kwargs)
               ^^^^^^^^^^^^^^^^^^^^^^^^^^^^^^^^^^^^^^^^^^^^^^^^^^^^^^^^^^^^
  File "/home/userdm/code/env_pool/env_gh_ht21/lib/python3.11/site-packages/django/views/decorators/csrf.py", line 65, in _view_wrapper
    return view_func(request, *args, **kwargs)
           ^^^^^^^^^^^^^^^^^^^^^^^^^^^^^^^^^^^
  File "/home/userdm/code/env_pool/env_gh_ht21/lib/python3.11/site-packages/django/views/generic/base.py", line 104, in view
    return self.dispatch(request, *args, **kwargs)
           ^^^^^^^^^^^^^^^^^^^^^^^^^^^^^^^^^^^^^^^
  File "/home/userdm/code/env_pool/env_gh_ht21/lib/python3.11/site-packages/rest_framework/views.py", line 509, in dispatch
    response = self.handle_exception(exc)
               ^^^^^^^^^^^^^^^^^^^^^^^^^^
  File "/home/userdm/code/env_pool/env_gh_ht21/lib/python3.11/site-packages/rest_framework/views.py", line 469, in handle_exception
    self.raise_uncaught_exception(exc)
  File "/home/userdm/code/env_pool/env_gh_ht21/lib/python3.11/site-packages/rest_framework/views.py", line 480, in raise_uncaught_exception
    raise exc
  File "/home/userdm/code/env_pool/env_gh_ht21/lib/python3.11/site-packages/rest_framework/views.py", line 506, in dispatch
    response = handler(request, *args, **kwargs)
               ^^^^^^^^^^^^^^^^^^^^^^^^^^^^^^^^^
  File "/home/userdm/code/python-course/gh-hometask/HT_21/api/views.py", line 34, in get
    cart_data = request.session.get('product_data', []).get('cart_list', [])
                ^^^^^^^^^^^^^^^^^^^^^^^^^^^^^^^^^^^^^^^^^^^
AttributeError: 'list' object has no attribute 'get'
"GET /api/v1/cartlist/?format=json HTTP/1.1" 500 91235
Internal Server Error: /api/v1/cartlist/
Traceback (most recent call last):
  File "/home/userdm/code/env_pool/env_gh_ht21/lib/python3.11/site-packages/django/core/handlers/exception.py", line 55, in inner
    response = get_response(request)
               ^^^^^^^^^^^^^^^^^^^^^
  File "/home/userdm/code/env_pool/env_gh_ht21/lib/python3.11/site-packages/django/core/handlers/base.py", line 197, in _get_response
    response = wrapped_callback(request, *callback_args, **callback_kwargs)
               ^^^^^^^^^^^^^^^^^^^^^^^^^^^^^^^^^^^^^^^^^^^^^^^^^^^^^^^^^^^^
  File "/home/userdm/code/env_pool/env_gh_ht21/lib/python3.11/site-packages/django/views/decorators/csrf.py", line 65, in _view_wrapper
    return view_func(request, *args, **kwargs)
           ^^^^^^^^^^^^^^^^^^^^^^^^^^^^^^^^^^^
  File "/home/userdm/code/env_pool/env_gh_ht21/lib/python3.11/site-packages/django/views/generic/base.py", line 104, in view
    return self.dispatch(request, *args, **kwargs)
           ^^^^^^^^^^^^^^^^^^^^^^^^^^^^^^^^^^^^^^^
  File "/home/userdm/code/env_pool/env_gh_ht21/lib/python3.11/site-packages/rest_framework/views.py", line 509, in dispatch
    response = self.handle_exception(exc)
               ^^^^^^^^^^^^^^^^^^^^^^^^^^
  File "/home/userdm/code/env_pool/env_gh_ht21/lib/python3.11/site-packages/rest_framework/views.py", line 469, in handle_exception
    self.raise_uncaught_exception(exc)
  File "/home/userdm/code/env_pool/env_gh_ht21/lib/python3.11/site-packages/rest_framework/views.py", line 480, in raise_uncaught_exception
    raise exc
  File "/home/userdm/code/env_pool/env_gh_ht21/lib/python3.11/site-packages/rest_framework/views.py", line 506, in dispatch
    response = handler(request, *args, **kwargs)
               ^^^^^^^^^^^^^^^^^^^^^^^^^^^^^^^^^
  File "/home/userdm/code/python-course/gh-hometask/HT_21/api/views.py", line 34, in get
    cart_data = request.session.get('product_data', []).get('cart_list', [])
                ^^^^^^^^^^^^^^^^^^^^^^^^^^^^^^^^^^^^^^^^^^^
AttributeError: 'list' object has no attribute 'get'
"GET /api/v1/cartlist/?format=json HTTP/1.1" 500 92681
Internal Server Error: /api/v1/cartlist/1/
Traceback (most recent call last):
  File "/home/userdm/code/env_pool/env_gh_ht21/lib/python3.11/site-packages/django/core/handlers/exception.py", line 55, in inner
    response = get_response(request)
               ^^^^^^^^^^^^^^^^^^^^^
  File "/home/userdm/code/env_pool/env_gh_ht21/lib/python3.11/site-packages/django/core/handlers/base.py", line 197, in _get_response
    response = wrapped_callback(request, *callback_args, **callback_kwargs)
               ^^^^^^^^^^^^^^^^^^^^^^^^^^^^^^^^^^^^^^^^^^^^^^^^^^^^^^^^^^^^
  File "/home/userdm/code/env_pool/env_gh_ht21/lib/python3.11/site-packages/django/views/decorators/csrf.py", line 65, in _view_wrapper
    return view_func(request, *args, **kwargs)
           ^^^^^^^^^^^^^^^^^^^^^^^^^^^^^^^^^^^
  File "/home/userdm/code/env_pool/env_gh_ht21/lib/python3.11/site-packages/django/views/generic/base.py", line 104, in view
    return self.dispatch(request, *args, **kwargs)
           ^^^^^^^^^^^^^^^^^^^^^^^^^^^^^^^^^^^^^^^
  File "/home/userdm/code/env_pool/env_gh_ht21/lib/python3.11/site-packages/rest_framework/views.py", line 509, in dispatch
    response = self.handle_exception(exc)
               ^^^^^^^^^^^^^^^^^^^^^^^^^^
  File "/home/userdm/code/env_pool/env_gh_ht21/lib/python3.11/site-packages/rest_framework/views.py", line 469, in handle_exception
    self.raise_uncaught_exception(exc)
  File "/home/userdm/code/env_pool/env_gh_ht21/lib/python3.11/site-packages/rest_framework/views.py", line 480, in raise_uncaught_exception
    raise exc
  File "/home/userdm/code/env_pool/env_gh_ht21/lib/python3.11/site-packages/rest_framework/views.py", line 506, in dispatch
    response = handler(request, *args, **kwargs)
               ^^^^^^^^^^^^^^^^^^^^^^^^^^^^^^^^^
  File "/home/userdm/code/python-course/gh-hometask/HT_21/api/views.py", line 34, in get
    cart_data = request.session.get('product_data', []).get('cart_list', [])
                ^^^^^^^^^^^^^^^^^^^^^^^^^^^^^^^^^^^^^^^^^^^
AttributeError: 'list' object has no attribute 'get'
"GET /api/v1/cartlist/1/ HTTP/1.1" 500 91071
Internal Server Error: /api/v1/cartlist/1/
Traceback (most recent call last):
  File "/home/userdm/code/env_pool/env_gh_ht21/lib/python3.11/site-packages/django/core/handlers/exception.py", line 55, in inner
    response = get_response(request)
               ^^^^^^^^^^^^^^^^^^^^^
  File "/home/userdm/code/env_pool/env_gh_ht21/lib/python3.11/site-packages/django/core/handlers/base.py", line 197, in _get_response
    response = wrapped_callback(request, *callback_args, **callback_kwargs)
               ^^^^^^^^^^^^^^^^^^^^^^^^^^^^^^^^^^^^^^^^^^^^^^^^^^^^^^^^^^^^
  File "/home/userdm/code/env_pool/env_gh_ht21/lib/python3.11/site-packages/django/views/decorators/csrf.py", line 65, in _view_wrapper
    return view_func(request, *args, **kwargs)
           ^^^^^^^^^^^^^^^^^^^^^^^^^^^^^^^^^^^
  File "/home/userdm/code/env_pool/env_gh_ht21/lib/python3.11/site-packages/django/views/generic/base.py", line 104, in view
    return self.dispatch(request, *args, **kwargs)
           ^^^^^^^^^^^^^^^^^^^^^^^^^^^^^^^^^^^^^^^
  File "/home/userdm/code/env_pool/env_gh_ht21/lib/python3.11/site-packages/rest_framework/views.py", line 509, in dispatch
    response = self.handle_exception(exc)
               ^^^^^^^^^^^^^^^^^^^^^^^^^^
  File "/home/userdm/code/env_pool/env_gh_ht21/lib/python3.11/site-packages/rest_framework/views.py", line 469, in handle_exception
    self.raise_uncaught_exception(exc)
  File "/home/userdm/code/env_pool/env_gh_ht21/lib/python3.11/site-packages/rest_framework/views.py", line 480, in raise_uncaught_exception
    raise exc
  File "/home/userdm/code/env_pool/env_gh_ht21/lib/python3.11/site-packages/rest_framework/views.py", line 506, in dispatch
    response = handler(request, *args, **kwargs)
               ^^^^^^^^^^^^^^^^^^^^^^^^^^^^^^^^^
  File "/home/userdm/code/python-course/gh-hometask/HT_21/api/views.py", line 34, in get
    cart_data = request.session.get('product_data', []).get('cart_list', [])
                ^^^^^^^^^^^^^^^^^^^^^^^^^^^^^^^^^^^^^^^^^^^
AttributeError: 'list' object has no attribute 'get'
"GET /api/v1/cartlist/1/ HTTP/1.1" 500 93440
Internal Server Error: /api/v1/cartlist/
Traceback (most recent call last):
  File "/home/userdm/code/env_pool/env_gh_ht21/lib/python3.11/site-packages/django/core/handlers/exception.py", line 55, in inner
    response = get_response(request)
               ^^^^^^^^^^^^^^^^^^^^^
  File "/home/userdm/code/env_pool/env_gh_ht21/lib/python3.11/site-packages/django/core/handlers/base.py", line 197, in _get_response
    response = wrapped_callback(request, *callback_args, **callback_kwargs)
               ^^^^^^^^^^^^^^^^^^^^^^^^^^^^^^^^^^^^^^^^^^^^^^^^^^^^^^^^^^^^
  File "/home/userdm/code/env_pool/env_gh_ht21/lib/python3.11/site-packages/django/views/decorators/csrf.py", line 65, in _view_wrapper
    return view_func(request, *args, **kwargs)
           ^^^^^^^^^^^^^^^^^^^^^^^^^^^^^^^^^^^
  File "/home/userdm/code/env_pool/env_gh_ht21/lib/python3.11/site-packages/django/views/generic/base.py", line 104, in view
    return self.dispatch(request, *args, **kwargs)
           ^^^^^^^^^^^^^^^^^^^^^^^^^^^^^^^^^^^^^^^
  File "/home/userdm/code/env_pool/env_gh_ht21/lib/python3.11/site-packages/rest_framework/views.py", line 509, in dispatch
    response = self.handle_exception(exc)
               ^^^^^^^^^^^^^^^^^^^^^^^^^^
  File "/home/userdm/code/env_pool/env_gh_ht21/lib/python3.11/site-packages/rest_framework/views.py", line 469, in handle_exception
    self.raise_uncaught_exception(exc)
  File "/home/userdm/code/env_pool/env_gh_ht21/lib/python3.11/site-packages/rest_framework/views.py", line 480, in raise_uncaught_exception
    raise exc
  File "/home/userdm/code/env_pool/env_gh_ht21/lib/python3.11/site-packages/rest_framework/views.py", line 506, in dispatch
    response = handler(request, *args, **kwargs)
               ^^^^^^^^^^^^^^^^^^^^^^^^^^^^^^^^^
  File "/home/userdm/code/python-course/gh-hometask/HT_21/api/views.py", line 34, in get
    cart_data = request.session.get('product_data', []).get('cart_list', [])
                ^^^^^^^^^^^^^^^^^^^^^^^^^^^^^^^^^^^^^^^^^^^
AttributeError: 'list' object has no attribute 'get'
"GET /api/v1/cartlist/ HTTP/1.1" 500 93289
Internal Server Error: /api/v1/cartlist/
Traceback (most recent call last):
  File "/home/userdm/code/env_pool/env_gh_ht21/lib/python3.11/site-packages/django/core/handlers/exception.py", line 55, in inner
    response = get_response(request)
               ^^^^^^^^^^^^^^^^^^^^^
  File "/home/userdm/code/env_pool/env_gh_ht21/lib/python3.11/site-packages/django/core/handlers/base.py", line 197, in _get_response
    response = wrapped_callback(request, *callback_args, **callback_kwargs)
               ^^^^^^^^^^^^^^^^^^^^^^^^^^^^^^^^^^^^^^^^^^^^^^^^^^^^^^^^^^^^
  File "/home/userdm/code/env_pool/env_gh_ht21/lib/python3.11/site-packages/django/views/decorators/csrf.py", line 65, in _view_wrapper
    return view_func(request, *args, **kwargs)
           ^^^^^^^^^^^^^^^^^^^^^^^^^^^^^^^^^^^
  File "/home/userdm/code/env_pool/env_gh_ht21/lib/python3.11/site-packages/django/views/generic/base.py", line 104, in view
    return self.dispatch(request, *args, **kwargs)
           ^^^^^^^^^^^^^^^^^^^^^^^^^^^^^^^^^^^^^^^
  File "/home/userdm/code/env_pool/env_gh_ht21/lib/python3.11/site-packages/rest_framework/views.py", line 509, in dispatch
    response = self.handle_exception(exc)
               ^^^^^^^^^^^^^^^^^^^^^^^^^^
  File "/home/userdm/code/env_pool/env_gh_ht21/lib/python3.11/site-packages/rest_framework/views.py", line 469, in handle_exception
    self.raise_uncaught_exception(exc)
  File "/home/userdm/code/env_pool/env_gh_ht21/lib/python3.11/site-packages/rest_framework/views.py", line 480, in raise_uncaught_exception
    raise exc
  File "/home/userdm/code/env_pool/env_gh_ht21/lib/python3.11/site-packages/rest_framework/views.py", line 506, in dispatch
    response = handler(request, *args, **kwargs)
               ^^^^^^^^^^^^^^^^^^^^^^^^^^^^^^^^^
  File "/home/userdm/code/python-course/gh-hometask/HT_21/api/views.py", line 34, in get
    cart_data = request.session.get('product_data', []).get('cart_list', [])
                ^^^^^^^^^^^^^^^^^^^^^^^^^^^^^^^^^^^^^^^^^^^
AttributeError: 'list' object has no attribute 'get'
"GET /api/v1/cartlist/ HTTP/1.1" 500 93289
Internal Server Error: /api/v1/cartlist/3/
Traceback (most recent call last):
  File "/home/userdm/code/env_pool/env_gh_ht21/lib/python3.11/site-packages/django/core/handlers/exception.py", line 55, in inner
    response = get_response(request)
               ^^^^^^^^^^^^^^^^^^^^^
  File "/home/userdm/code/env_pool/env_gh_ht21/lib/python3.11/site-packages/django/core/handlers/base.py", line 197, in _get_response
    response = wrapped_callback(request, *callback_args, **callback_kwargs)
               ^^^^^^^^^^^^^^^^^^^^^^^^^^^^^^^^^^^^^^^^^^^^^^^^^^^^^^^^^^^^
  File "/home/userdm/code/env_pool/env_gh_ht21/lib/python3.11/site-packages/django/views/decorators/csrf.py", line 65, in _view_wrapper
    return view_func(request, *args, **kwargs)
           ^^^^^^^^^^^^^^^^^^^^^^^^^^^^^^^^^^^
  File "/home/userdm/code/env_pool/env_gh_ht21/lib/python3.11/site-packages/django/views/generic/base.py", line 104, in view
    return self.dispatch(request, *args, **kwargs)
           ^^^^^^^^^^^^^^^^^^^^^^^^^^^^^^^^^^^^^^^
  File "/home/userdm/code/env_pool/env_gh_ht21/lib/python3.11/site-packages/rest_framework/views.py", line 509, in dispatch
    response = self.handle_exception(exc)
               ^^^^^^^^^^^^^^^^^^^^^^^^^^
  File "/home/userdm/code/env_pool/env_gh_ht21/lib/python3.11/site-packages/rest_framework/views.py", line 469, in handle_exception
    self.raise_uncaught_exception(exc)
  File "/home/userdm/code/env_pool/env_gh_ht21/lib/python3.11/site-packages/rest_framework/views.py", line 480, in raise_uncaught_exception
    raise exc
  File "/home/userdm/code/env_pool/env_gh_ht21/lib/python3.11/site-packages/rest_framework/views.py", line 506, in dispatch
    response = handler(request, *args, **kwargs)
               ^^^^^^^^^^^^^^^^^^^^^^^^^^^^^^^^^
  File "/home/userdm/code/python-course/gh-hometask/HT_21/api/views.py", line 60, in delete
    print(session['product_data']['cart_list'])
          ^^^^^^^
NameError: name 'session' is not defined
"DELETE /api/v1/cartlist/3/ HTTP/1.1" 500 94562
Internal Server Error: /api/v1/cartlist/5/
Traceback (most recent call last):
  File "/home/userdm/code/env_pool/env_gh_ht21/lib/python3.11/site-packages/django/core/handlers/exception.py", line 55, in inner
    response = get_response(request)
               ^^^^^^^^^^^^^^^^^^^^^
  File "/home/userdm/code/env_pool/env_gh_ht21/lib/python3.11/site-packages/django/core/handlers/base.py", line 197, in _get_response
    response = wrapped_callback(request, *callback_args, **callback_kwargs)
               ^^^^^^^^^^^^^^^^^^^^^^^^^^^^^^^^^^^^^^^^^^^^^^^^^^^^^^^^^^^^
  File "/home/userdm/code/env_pool/env_gh_ht21/lib/python3.11/site-packages/django/views/decorators/csrf.py", line 65, in _view_wrapper
    return view_func(request, *args, **kwargs)
           ^^^^^^^^^^^^^^^^^^^^^^^^^^^^^^^^^^^
  File "/home/userdm/code/env_pool/env_gh_ht21/lib/python3.11/site-packages/django/views/generic/base.py", line 104, in view
    return self.dispatch(request, *args, **kwargs)
           ^^^^^^^^^^^^^^^^^^^^^^^^^^^^^^^^^^^^^^^
  File "/home/userdm/code/env_pool/env_gh_ht21/lib/python3.11/site-packages/rest_framework/views.py", line 509, in dispatch
    response = self.handle_exception(exc)
               ^^^^^^^^^^^^^^^^^^^^^^^^^^
  File "/home/userdm/code/env_pool/env_gh_ht21/lib/python3.11/site-packages/rest_framework/views.py", line 469, in handle_exception
    self.raise_uncaught_exception(exc)
  File "/home/userdm/code/env_pool/env_gh_ht21/lib/python3.11/site-packages/rest_framework/views.py", line 480, in raise_uncaught_exception
    raise exc
  File "/home/userdm/code/env_pool/env_gh_ht21/lib/python3.11/site-packages/rest_framework/views.py", line 506, in dispatch
    response = handler(request, *args, **kwargs)
               ^^^^^^^^^^^^^^^^^^^^^^^^^^^^^^^^^
  File "/home/userdm/code/python-course/gh-hometask/HT_21/api/views.py", line 60, in delete
    print(session.get('product_data').get('cart_list'))
          ^^^^^^^
NameError: name 'session' is not defined
"DELETE /api/v1/cartlist/5/ HTTP/1.1" 500 94580
Internal Server Error: /api/v1/cartlist/2/
Traceback (most recent call last):
  File "/home/userdm/code/env_pool/env_gh_ht21/lib/python3.11/site-packages/django/core/handlers/exception.py", line 55, in inner
    response = get_response(request)
               ^^^^^^^^^^^^^^^^^^^^^
  File "/home/userdm/code/env_pool/env_gh_ht21/lib/python3.11/site-packages/django/core/handlers/base.py", line 197, in _get_response
    response = wrapped_callback(request, *callback_args, **callback_kwargs)
               ^^^^^^^^^^^^^^^^^^^^^^^^^^^^^^^^^^^^^^^^^^^^^^^^^^^^^^^^^^^^
  File "/home/userdm/code/env_pool/env_gh_ht21/lib/python3.11/site-packages/django/views/decorators/csrf.py", line 65, in _view_wrapper
    return view_func(request, *args, **kwargs)
           ^^^^^^^^^^^^^^^^^^^^^^^^^^^^^^^^^^^
  File "/home/userdm/code/env_pool/env_gh_ht21/lib/python3.11/site-packages/django/views/generic/base.py", line 104, in view
    return self.dispatch(request, *args, **kwargs)
           ^^^^^^^^^^^^^^^^^^^^^^^^^^^^^^^^^^^^^^^
  File "/home/userdm/code/env_pool/env_gh_ht21/lib/python3.11/site-packages/rest_framework/views.py", line 509, in dispatch
    response = self.handle_exception(exc)
               ^^^^^^^^^^^^^^^^^^^^^^^^^^
  File "/home/userdm/code/env_pool/env_gh_ht21/lib/python3.11/site-packages/rest_framework/views.py", line 469, in handle_exception
    self.raise_uncaught_exception(exc)
  File "/home/userdm/code/env_pool/env_gh_ht21/lib/python3.11/site-packages/rest_framework/views.py", line 480, in raise_uncaught_exception
    raise exc
  File "/home/userdm/code/env_pool/env_gh_ht21/lib/python3.11/site-packages/rest_framework/views.py", line 506, in dispatch
    response = handler(request, *args, **kwargs)
               ^^^^^^^^^^^^^^^^^^^^^^^^^^^^^^^^^
  File "/home/userdm/code/python-course/gh-hometask/HT_21/api/views.py", line 46, in delete
    cart_data = request.session.get('product_data', []).get('cart_list', [])
                ^^^^^^^^^^^^^^^^^^^^^^^^^^^^^^^^^^^^^^^^^^^
AttributeError: 'list' object has no attribute 'get'
"DELETE /api/v1/cartlist/2/ HTTP/1.1" 500 93752
Internal Server Error: /api/v1/cartlist/2/
Traceback (most recent call last):
  File "/home/userdm/code/env_pool/env_gh_ht21/lib/python3.11/site-packages/django/core/handlers/exception.py", line 55, in inner
    response = get_response(request)
               ^^^^^^^^^^^^^^^^^^^^^
  File "/home/userdm/code/env_pool/env_gh_ht21/lib/python3.11/site-packages/django/core/handlers/base.py", line 197, in _get_response
    response = wrapped_callback(request, *callback_args, **callback_kwargs)
               ^^^^^^^^^^^^^^^^^^^^^^^^^^^^^^^^^^^^^^^^^^^^^^^^^^^^^^^^^^^^
  File "/home/userdm/code/env_pool/env_gh_ht21/lib/python3.11/site-packages/django/views/decorators/csrf.py", line 65, in _view_wrapper
    return view_func(request, *args, **kwargs)
           ^^^^^^^^^^^^^^^^^^^^^^^^^^^^^^^^^^^
  File "/home/userdm/code/env_pool/env_gh_ht21/lib/python3.11/site-packages/django/views/generic/base.py", line 104, in view
    return self.dispatch(request, *args, **kwargs)
           ^^^^^^^^^^^^^^^^^^^^^^^^^^^^^^^^^^^^^^^
  File "/home/userdm/code/env_pool/env_gh_ht21/lib/python3.11/site-packages/rest_framework/views.py", line 509, in dispatch
    response = self.handle_exception(exc)
               ^^^^^^^^^^^^^^^^^^^^^^^^^^
  File "/home/userdm/code/env_pool/env_gh_ht21/lib/python3.11/site-packages/rest_framework/views.py", line 469, in handle_exception
    self.raise_uncaught_exception(exc)
  File "/home/userdm/code/env_pool/env_gh_ht21/lib/python3.11/site-packages/rest_framework/views.py", line 480, in raise_uncaught_exception
    raise exc
  File "/home/userdm/code/env_pool/env_gh_ht21/lib/python3.11/site-packages/rest_framework/views.py", line 506, in dispatch
    response = handler(request, *args, **kwargs)
               ^^^^^^^^^^^^^^^^^^^^^^^^^^^^^^^^^
  File "/home/userdm/code/python-course/gh-hometask/HT_21/api/views.py", line 54, in put
    if item['product_id'] == product_id_to_update:
                             ^^^^^^^^^^^^^^^^^^^^
NameError: name 'product_id_to_update' is not defined
"PUT /api/v1/cartlist/2/ HTTP/1.1" 500 94497
Internal Server Error: /api/v1/cartlist/update/2/
Traceback (most recent call last):
  File "/home/userdm/code/env_pool/env_gh_ht21/lib/python3.11/site-packages/django/core/handlers/exception.py", line 55, in inner
    response = get_response(request)
               ^^^^^^^^^^^^^^^^^^^^^
  File "/home/userdm/code/env_pool/env_gh_ht21/lib/python3.11/site-packages/django/core/handlers/base.py", line 197, in _get_response
    response = wrapped_callback(request, *callback_args, **callback_kwargs)
               ^^^^^^^^^^^^^^^^^^^^^^^^^^^^^^^^^^^^^^^^^^^^^^^^^^^^^^^^^^^^
  File "/home/userdm/code/env_pool/env_gh_ht21/lib/python3.11/site-packages/django/views/decorators/csrf.py", line 65, in _view_wrapper
    return view_func(request, *args, **kwargs)
           ^^^^^^^^^^^^^^^^^^^^^^^^^^^^^^^^^^^
  File "/home/userdm/code/env_pool/env_gh_ht21/lib/python3.11/site-packages/django/views/generic/base.py", line 104, in view
    return self.dispatch(request, *args, **kwargs)
           ^^^^^^^^^^^^^^^^^^^^^^^^^^^^^^^^^^^^^^^
  File "/home/userdm/code/env_pool/env_gh_ht21/lib/python3.11/site-packages/rest_framework/views.py", line 509, in dispatch
    response = self.handle_exception(exc)
               ^^^^^^^^^^^^^^^^^^^^^^^^^^
  File "/home/userdm/code/env_pool/env_gh_ht21/lib/python3.11/site-packages/rest_framework/views.py", line 469, in handle_exception
    self.raise_uncaught_exception(exc)
  File "/home/userdm/code/env_pool/env_gh_ht21/lib/python3.11/site-packages/rest_framework/views.py", line 480, in raise_uncaught_exception
    raise exc
  File "/home/userdm/code/env_pool/env_gh_ht21/lib/python3.11/site-packages/rest_framework/views.py", line 506, in dispatch
    response = handler(request, *args, **kwargs)
               ^^^^^^^^^^^^^^^^^^^^^^^^^^^^^^^^^
  File "/home/userdm/code/python-course/gh-hometask/HT_21/api/views.py", line 54, in put
    if item['product_id'] == product_id_to_update:
                             ^^^^^^^^^^^^^^^^^^^^
NameError: name 'product_id_to_update' is not defined
"PUT /api/v1/cartlist/update/2/ HTTP/1.1" 500 94616
Internal Server Error: /api/v1/cartlist/
Traceback (most recent call last):
  File "/home/userdm/code/env_pool/env_gh_ht21/lib/python3.11/site-packages/django/core/handlers/exception.py", line 55, in inner
    response = get_response(request)
               ^^^^^^^^^^^^^^^^^^^^^
  File "/home/userdm/code/env_pool/env_gh_ht21/lib/python3.11/site-packages/django/core/handlers/base.py", line 197, in _get_response
    response = wrapped_callback(request, *callback_args, **callback_kwargs)
               ^^^^^^^^^^^^^^^^^^^^^^^^^^^^^^^^^^^^^^^^^^^^^^^^^^^^^^^^^^^^
  File "/home/userdm/code/env_pool/env_gh_ht21/lib/python3.11/site-packages/django/views/decorators/csrf.py", line 65, in _view_wrapper
    return view_func(request, *args, **kwargs)
           ^^^^^^^^^^^^^^^^^^^^^^^^^^^^^^^^^^^
  File "/home/userdm/code/env_pool/env_gh_ht21/lib/python3.11/site-packages/django/views/generic/base.py", line 104, in view
    return self.dispatch(request, *args, **kwargs)
           ^^^^^^^^^^^^^^^^^^^^^^^^^^^^^^^^^^^^^^^
  File "/home/userdm/code/env_pool/env_gh_ht21/lib/python3.11/site-packages/rest_framework/views.py", line 509, in dispatch
    response = self.handle_exception(exc)
               ^^^^^^^^^^^^^^^^^^^^^^^^^^
  File "/home/userdm/code/env_pool/env_gh_ht21/lib/python3.11/site-packages/rest_framework/views.py", line 469, in handle_exception
    self.raise_uncaught_exception(exc)
  File "/home/userdm/code/env_pool/env_gh_ht21/lib/python3.11/site-packages/rest_framework/views.py", line 480, in raise_uncaught_exception
    raise exc
  File "/home/userdm/code/env_pool/env_gh_ht21/lib/python3.11/site-packages/rest_framework/views.py", line 506, in dispatch
    response = handler(request, *args, **kwargs)
               ^^^^^^^^^^^^^^^^^^^^^^^^^^^^^^^^^
  File "/home/userdm/code/python-course/gh-hometask/HT_21/api/views.py", line 44, in post
    id_product_list = Product.get.objects.all()
                      ^^^^^^^^^^^
AttributeError: type object 'Product' has no attribute 'get'
"POST /api/v1/cartlist/ HTTP/1.1" 500 93239
Internal Server Error: /api/v1/cartlist/
Traceback (most recent call last):
  File "/home/userdm/code/env_pool/env_gh_ht21/lib/python3.11/site-packages/django/core/handlers/exception.py", line 55, in inner
    response = get_response(request)
               ^^^^^^^^^^^^^^^^^^^^^
  File "/home/userdm/code/env_pool/env_gh_ht21/lib/python3.11/site-packages/django/core/handlers/base.py", line 197, in _get_response
    response = wrapped_callback(request, *callback_args, **callback_kwargs)
               ^^^^^^^^^^^^^^^^^^^^^^^^^^^^^^^^^^^^^^^^^^^^^^^^^^^^^^^^^^^^
  File "/home/userdm/code/env_pool/env_gh_ht21/lib/python3.11/site-packages/django/views/decorators/csrf.py", line 65, in _view_wrapper
    return view_func(request, *args, **kwargs)
           ^^^^^^^^^^^^^^^^^^^^^^^^^^^^^^^^^^^
  File "/home/userdm/code/env_pool/env_gh_ht21/lib/python3.11/site-packages/django/views/generic/base.py", line 104, in view
    return self.dispatch(request, *args, **kwargs)
           ^^^^^^^^^^^^^^^^^^^^^^^^^^^^^^^^^^^^^^^
  File "/home/userdm/code/env_pool/env_gh_ht21/lib/python3.11/site-packages/rest_framework/views.py", line 511, in dispatch
    self.response = self.finalize_response(request, response, *args, **kwargs)
                    ^^^^^^^^^^^^^^^^^^^^^^^^^^^^^^^^^^^^^^^^^^^^^^^^^^^^^^^^^^
  File "/home/userdm/code/env_pool/env_gh_ht21/lib/python3.11/site-packages/rest_framework/views.py", line 423, in finalize_response
    assert isinstance(response, HttpResponseBase), (
AssertionError: Expected a `Response`, `HttpResponse` or `HttpStreamingResponse` to be returned from the view, but received a `<class 'NoneType'>`
"POST /api/v1/cartlist/ HTTP/1.1" 500 80177
Internal Server Error: /api/v1/cartlist/2/
Traceback (most recent call last):
  File "/home/userdm/code/env_pool/env_gh_ht21/lib/python3.11/site-packages/django/core/handlers/exception.py", line 55, in inner
    response = get_response(request)
               ^^^^^^^^^^^^^^^^^^^^^
  File "/home/userdm/code/env_pool/env_gh_ht21/lib/python3.11/site-packages/django/core/handlers/base.py", line 197, in _get_response
    response = wrapped_callback(request, *callback_args, **callback_kwargs)
               ^^^^^^^^^^^^^^^^^^^^^^^^^^^^^^^^^^^^^^^^^^^^^^^^^^^^^^^^^^^^
  File "/home/userdm/code/env_pool/env_gh_ht21/lib/python3.11/site-packages/django/views/decorators/csrf.py", line 65, in _view_wrapper
    return view_func(request, *args, **kwargs)
           ^^^^^^^^^^^^^^^^^^^^^^^^^^^^^^^^^^^
  File "/home/userdm/code/env_pool/env_gh_ht21/lib/python3.11/site-packages/django/views/generic/base.py", line 104, in view
    return self.dispatch(request, *args, **kwargs)
           ^^^^^^^^^^^^^^^^^^^^^^^^^^^^^^^^^^^^^^^
  File "/home/userdm/code/env_pool/env_gh_ht21/lib/python3.11/site-packages/rest_framework/views.py", line 509, in dispatch
    response = self.handle_exception(exc)
               ^^^^^^^^^^^^^^^^^^^^^^^^^^
  File "/home/userdm/code/env_pool/env_gh_ht21/lib/python3.11/site-packages/rest_framework/views.py", line 469, in handle_exception
    self.raise_uncaught_exception(exc)
  File "/home/userdm/code/env_pool/env_gh_ht21/lib/python3.11/site-packages/rest_framework/views.py", line 480, in raise_uncaught_exception
    raise exc
  File "/home/userdm/code/env_pool/env_gh_ht21/lib/python3.11/site-packages/rest_framework/views.py", line 506, in dispatch
    response = handler(request, *args, **kwargs)
               ^^^^^^^^^^^^^^^^^^^^^^^^^^^^^^^^^
  File "/home/userdm/code/python-course/gh-hometask/HT_21/api/views.py", line 46, in post
    print(id_product.get('id'))
          ^^^^^^^^^^^^^^
AttributeError: 'Product' object has no attribute 'get'
"POST /api/v1/cartlist/2/ HTTP/1.1" 500 95393
Internal Server Error: /api/v1/cartlist/3/
Traceback (most recent call last):
  File "/home/userdm/code/env_pool/env_gh_ht21/lib/python3.11/site-packages/django/core/handlers/exception.py", line 55, in inner
    response = get_response(request)
               ^^^^^^^^^^^^^^^^^^^^^
  File "/home/userdm/code/env_pool/env_gh_ht21/lib/python3.11/site-packages/django/core/handlers/base.py", line 197, in _get_response
    response = wrapped_callback(request, *callback_args, **callback_kwargs)
               ^^^^^^^^^^^^^^^^^^^^^^^^^^^^^^^^^^^^^^^^^^^^^^^^^^^^^^^^^^^^
  File "/home/userdm/code/env_pool/env_gh_ht21/lib/python3.11/site-packages/django/views/decorators/csrf.py", line 65, in _view_wrapper
    return view_func(request, *args, **kwargs)
           ^^^^^^^^^^^^^^^^^^^^^^^^^^^^^^^^^^^
  File "/home/userdm/code/env_pool/env_gh_ht21/lib/python3.11/site-packages/django/views/generic/base.py", line 104, in view
    return self.dispatch(request, *args, **kwargs)
           ^^^^^^^^^^^^^^^^^^^^^^^^^^^^^^^^^^^^^^^
  File "/home/userdm/code/env_pool/env_gh_ht21/lib/python3.11/site-packages/rest_framework/views.py", line 511, in dispatch
    self.response = self.finalize_response(request, response, *args, **kwargs)
                    ^^^^^^^^^^^^^^^^^^^^^^^^^^^^^^^^^^^^^^^^^^^^^^^^^^^^^^^^^^
  File "/home/userdm/code/env_pool/env_gh_ht21/lib/python3.11/site-packages/rest_framework/views.py", line 423, in finalize_response
    assert isinstance(response, HttpResponseBase), (
AssertionError: Expected a `Response`, `HttpResponse` or `HttpStreamingResponse` to be returned from the view, but received a `<class 'NoneType'>`
"POST /api/v1/cartlist/3/ HTTP/1.1" 500 80290
Internal Server Error: /api/v1/cartlist/4/
Traceback (most recent call last):
  File "/home/userdm/code/env_pool/env_gh_ht21/lib/python3.11/site-packages/django/core/handlers/exception.py", line 55, in inner
    response = get_response(request)
               ^^^^^^^^^^^^^^^^^^^^^
  File "/home/userdm/code/env_pool/env_gh_ht21/lib/python3.11/site-packages/django/core/handlers/base.py", line 197, in _get_response
    response = wrapped_callback(request, *callback_args, **callback_kwargs)
               ^^^^^^^^^^^^^^^^^^^^^^^^^^^^^^^^^^^^^^^^^^^^^^^^^^^^^^^^^^^^
  File "/home/userdm/code/env_pool/env_gh_ht21/lib/python3.11/site-packages/django/views/decorators/csrf.py", line 65, in _view_wrapper
    return view_func(request, *args, **kwargs)
           ^^^^^^^^^^^^^^^^^^^^^^^^^^^^^^^^^^^
  File "/home/userdm/code/env_pool/env_gh_ht21/lib/python3.11/site-packages/django/views/generic/base.py", line 104, in view
    return self.dispatch(request, *args, **kwargs)
           ^^^^^^^^^^^^^^^^^^^^^^^^^^^^^^^^^^^^^^^
  File "/home/userdm/code/env_pool/env_gh_ht21/lib/python3.11/site-packages/rest_framework/views.py", line 509, in dispatch
    response = self.handle_exception(exc)
               ^^^^^^^^^^^^^^^^^^^^^^^^^^
  File "/home/userdm/code/env_pool/env_gh_ht21/lib/python3.11/site-packages/rest_framework/views.py", line 469, in handle_exception
    self.raise_uncaught_exception(exc)
  File "/home/userdm/code/env_pool/env_gh_ht21/lib/python3.11/site-packages/rest_framework/views.py", line 480, in raise_uncaught_exception
    raise exc
  File "/home/userdm/code/env_pool/env_gh_ht21/lib/python3.11/site-packages/rest_framework/views.py", line 506, in dispatch
    response = handler(request, *args, **kwargs)
               ^^^^^^^^^^^^^^^^^^^^^^^^^^^^^^^^^
  File "/home/userdm/code/python-course/gh-hometask/HT_21/api/views.py", line 47, in post
    print(request.POST.key())
          ^^^^^^^^^^^^^^^^
AttributeError: 'QueryDict' object has no attribute 'key'
"POST /api/v1/cartlist/4/ HTTP/1.1" 500 95469
Internal Server Error: /api/v1/cartlist/
Traceback (most recent call last):
  File "/home/userdm/code/env_pool/env_gh_ht21/lib/python3.11/site-packages/django/core/handlers/exception.py", line 55, in inner
    response = get_response(request)
               ^^^^^^^^^^^^^^^^^^^^^
  File "/home/userdm/code/env_pool/env_gh_ht21/lib/python3.11/site-packages/django/core/handlers/base.py", line 197, in _get_response
    response = wrapped_callback(request, *callback_args, **callback_kwargs)
               ^^^^^^^^^^^^^^^^^^^^^^^^^^^^^^^^^^^^^^^^^^^^^^^^^^^^^^^^^^^^
  File "/home/userdm/code/env_pool/env_gh_ht21/lib/python3.11/site-packages/django/views/decorators/csrf.py", line 65, in _view_wrapper
    return view_func(request, *args, **kwargs)
           ^^^^^^^^^^^^^^^^^^^^^^^^^^^^^^^^^^^
  File "/home/userdm/code/env_pool/env_gh_ht21/lib/python3.11/site-packages/django/views/generic/base.py", line 104, in view
    return self.dispatch(request, *args, **kwargs)
           ^^^^^^^^^^^^^^^^^^^^^^^^^^^^^^^^^^^^^^^
  File "/home/userdm/code/env_pool/env_gh_ht21/lib/python3.11/site-packages/rest_framework/views.py", line 511, in dispatch
    self.response = self.finalize_response(request, response, *args, **kwargs)
                    ^^^^^^^^^^^^^^^^^^^^^^^^^^^^^^^^^^^^^^^^^^^^^^^^^^^^^^^^^^
  File "/home/userdm/code/env_pool/env_gh_ht21/lib/python3.11/site-packages/rest_framework/views.py", line 423, in finalize_response
    assert isinstance(response, HttpResponseBase), (
AssertionError: Expected a `Response`, `HttpResponse` or `HttpStreamingResponse` to be returned from the view, but received a `<class 'NoneType'>`
"POST /api/v1/cartlist/ HTTP/1.1" 500 80177
Internal Server Error: /api/v1/cartlist/
Traceback (most recent call last):
  File "/home/userdm/code/env_pool/env_gh_ht21/lib/python3.11/site-packages/django/core/handlers/exception.py", line 55, in inner
    response = get_response(request)
               ^^^^^^^^^^^^^^^^^^^^^
  File "/home/userdm/code/env_pool/env_gh_ht21/lib/python3.11/site-packages/django/core/handlers/base.py", line 197, in _get_response
    response = wrapped_callback(request, *callback_args, **callback_kwargs)
               ^^^^^^^^^^^^^^^^^^^^^^^^^^^^^^^^^^^^^^^^^^^^^^^^^^^^^^^^^^^^
  File "/home/userdm/code/env_pool/env_gh_ht21/lib/python3.11/site-packages/django/views/decorators/csrf.py", line 65, in _view_wrapper
    return view_func(request, *args, **kwargs)
           ^^^^^^^^^^^^^^^^^^^^^^^^^^^^^^^^^^^
  File "/home/userdm/code/env_pool/env_gh_ht21/lib/python3.11/site-packages/django/views/generic/base.py", line 104, in view
    return self.dispatch(request, *args, **kwargs)
           ^^^^^^^^^^^^^^^^^^^^^^^^^^^^^^^^^^^^^^^
  File "/home/userdm/code/env_pool/env_gh_ht21/lib/python3.11/site-packages/rest_framework/views.py", line 511, in dispatch
    self.response = self.finalize_response(request, response, *args, **kwargs)
                    ^^^^^^^^^^^^^^^^^^^^^^^^^^^^^^^^^^^^^^^^^^^^^^^^^^^^^^^^^^
  File "/home/userdm/code/env_pool/env_gh_ht21/lib/python3.11/site-packages/rest_framework/views.py", line 423, in finalize_response
    assert isinstance(response, HttpResponseBase), (
AssertionError: Expected a `Response`, `HttpResponse` or `HttpStreamingResponse` to be returned from the view, but received a `<class 'NoneType'>`
"POST /api/v1/cartlist/ HTTP/1.1" 500 80177
Internal Server Error: /api/v1/cartlist/
Traceback (most recent call last):
  File "/home/userdm/code/env_pool/env_gh_ht21/lib/python3.11/site-packages/django/core/handlers/exception.py", line 55, in inner
    response = get_response(request)
               ^^^^^^^^^^^^^^^^^^^^^
  File "/home/userdm/code/env_pool/env_gh_ht21/lib/python3.11/site-packages/django/core/handlers/base.py", line 197, in _get_response
    response = wrapped_callback(request, *callback_args, **callback_kwargs)
               ^^^^^^^^^^^^^^^^^^^^^^^^^^^^^^^^^^^^^^^^^^^^^^^^^^^^^^^^^^^^
  File "/home/userdm/code/env_pool/env_gh_ht21/lib/python3.11/site-packages/django/views/decorators/csrf.py", line 65, in _view_wrapper
    return view_func(request, *args, **kwargs)
           ^^^^^^^^^^^^^^^^^^^^^^^^^^^^^^^^^^^
  File "/home/userdm/code/env_pool/env_gh_ht21/lib/python3.11/site-packages/django/views/generic/base.py", line 104, in view
    return self.dispatch(request, *args, **kwargs)
           ^^^^^^^^^^^^^^^^^^^^^^^^^^^^^^^^^^^^^^^
  File "/home/userdm/code/env_pool/env_gh_ht21/lib/python3.11/site-packages/rest_framework/views.py", line 511, in dispatch
    self.response = self.finalize_response(request, response, *args, **kwargs)
                    ^^^^^^^^^^^^^^^^^^^^^^^^^^^^^^^^^^^^^^^^^^^^^^^^^^^^^^^^^^
  File "/home/userdm/code/env_pool/env_gh_ht21/lib/python3.11/site-packages/rest_framework/views.py", line 423, in finalize_response
    assert isinstance(response, HttpResponseBase), (
AssertionError: Expected a `Response`, `HttpResponse` or `HttpStreamingResponse` to be returned from the view, but received a `<class 'NoneType'>`
"POST /api/v1/cartlist/ HTTP/1.1" 500 80177
Internal Server Error: /api/v1/cartlist/
Traceback (most recent call last):
  File "/home/userdm/code/env_pool/env_gh_ht21/lib/python3.11/site-packages/django/core/handlers/exception.py", line 55, in inner
    response = get_response(request)
               ^^^^^^^^^^^^^^^^^^^^^
  File "/home/userdm/code/env_pool/env_gh_ht21/lib/python3.11/site-packages/django/core/handlers/base.py", line 197, in _get_response
    response = wrapped_callback(request, *callback_args, **callback_kwargs)
               ^^^^^^^^^^^^^^^^^^^^^^^^^^^^^^^^^^^^^^^^^^^^^^^^^^^^^^^^^^^^
  File "/home/userdm/code/env_pool/env_gh_ht21/lib/python3.11/site-packages/django/views/decorators/csrf.py", line 65, in _view_wrapper
    return view_func(request, *args, **kwargs)
           ^^^^^^^^^^^^^^^^^^^^^^^^^^^^^^^^^^^
  File "/home/userdm/code/env_pool/env_gh_ht21/lib/python3.11/site-packages/django/views/generic/base.py", line 104, in view
    return self.dispatch(request, *args, **kwargs)
           ^^^^^^^^^^^^^^^^^^^^^^^^^^^^^^^^^^^^^^^
  File "/home/userdm/code/env_pool/env_gh_ht21/lib/python3.11/site-packages/rest_framework/views.py", line 511, in dispatch
    self.response = self.finalize_response(request, response, *args, **kwargs)
                    ^^^^^^^^^^^^^^^^^^^^^^^^^^^^^^^^^^^^^^^^^^^^^^^^^^^^^^^^^^
  File "/home/userdm/code/env_pool/env_gh_ht21/lib/python3.11/site-packages/rest_framework/views.py", line 423, in finalize_response
    assert isinstance(response, HttpResponseBase), (
AssertionError: Expected a `Response`, `HttpResponse` or `HttpStreamingResponse` to be returned from the view, but received a `<class 'NoneType'>`
"POST /api/v1/cartlist/ HTTP/1.1" 500 80177
Internal Server Error: /api/v1/cartlist/4/
Traceback (most recent call last):
  File "/home/userdm/code/env_pool/env_gh_ht21/lib/python3.11/site-packages/django/core/handlers/exception.py", line 55, in inner
    response = get_response(request)
               ^^^^^^^^^^^^^^^^^^^^^
  File "/home/userdm/code/env_pool/env_gh_ht21/lib/python3.11/site-packages/django/core/handlers/base.py", line 197, in _get_response
    response = wrapped_callback(request, *callback_args, **callback_kwargs)
               ^^^^^^^^^^^^^^^^^^^^^^^^^^^^^^^^^^^^^^^^^^^^^^^^^^^^^^^^^^^^
  File "/home/userdm/code/env_pool/env_gh_ht21/lib/python3.11/site-packages/django/views/decorators/csrf.py", line 65, in _view_wrapper
    return view_func(request, *args, **kwargs)
           ^^^^^^^^^^^^^^^^^^^^^^^^^^^^^^^^^^^
  File "/home/userdm/code/env_pool/env_gh_ht21/lib/python3.11/site-packages/django/views/generic/base.py", line 104, in view
    return self.dispatch(request, *args, **kwargs)
           ^^^^^^^^^^^^^^^^^^^^^^^^^^^^^^^^^^^^^^^
  File "/home/userdm/code/env_pool/env_gh_ht21/lib/python3.11/site-packages/rest_framework/views.py", line 509, in dispatch
    response = self.handle_exception(exc)
               ^^^^^^^^^^^^^^^^^^^^^^^^^^
  File "/home/userdm/code/env_pool/env_gh_ht21/lib/python3.11/site-packages/rest_framework/views.py", line 469, in handle_exception
    self.raise_uncaught_exception(exc)
  File "/home/userdm/code/env_pool/env_gh_ht21/lib/python3.11/site-packages/rest_framework/views.py", line 480, in raise_uncaught_exception
    raise exc
  File "/home/userdm/code/env_pool/env_gh_ht21/lib/python3.11/site-packages/rest_framework/views.py", line 506, in dispatch
    response = handler(request, *args, **kwargs)
               ^^^^^^^^^^^^^^^^^^^^^^^^^^^^^^^^^
  File "/home/userdm/code/python-course/gh-hometask/HT_21/api/views.py", line 47, in post
    quantity = request.POST.data.get('quantity')
               ^^^^^^^^^^^^^^^^^
AttributeError: 'QueryDict' object has no attribute 'data'
"POST /api/v1/cartlist/4/ HTTP/1.1" 500 95448
Internal Server Error: /api/v1/cartlist/
Traceback (most recent call last):
  File "/home/userdm/code/env_pool/env_gh_ht21/lib/python3.11/site-packages/django/core/handlers/exception.py", line 55, in inner
    response = get_response(request)
               ^^^^^^^^^^^^^^^^^^^^^
  File "/home/userdm/code/env_pool/env_gh_ht21/lib/python3.11/site-packages/django/core/handlers/base.py", line 197, in _get_response
    response = wrapped_callback(request, *callback_args, **callback_kwargs)
               ^^^^^^^^^^^^^^^^^^^^^^^^^^^^^^^^^^^^^^^^^^^^^^^^^^^^^^^^^^^^
  File "/home/userdm/code/env_pool/env_gh_ht21/lib/python3.11/site-packages/django/views/decorators/csrf.py", line 65, in _view_wrapper
    return view_func(request, *args, **kwargs)
           ^^^^^^^^^^^^^^^^^^^^^^^^^^^^^^^^^^^
  File "/home/userdm/code/env_pool/env_gh_ht21/lib/python3.11/site-packages/django/views/generic/base.py", line 104, in view
    return self.dispatch(request, *args, **kwargs)
           ^^^^^^^^^^^^^^^^^^^^^^^^^^^^^^^^^^^^^^^
  File "/home/userdm/code/env_pool/env_gh_ht21/lib/python3.11/site-packages/rest_framework/views.py", line 511, in dispatch
    self.response = self.finalize_response(request, response, *args, **kwargs)
                    ^^^^^^^^^^^^^^^^^^^^^^^^^^^^^^^^^^^^^^^^^^^^^^^^^^^^^^^^^^
  File "/home/userdm/code/env_pool/env_gh_ht21/lib/python3.11/site-packages/rest_framework/views.py", line 423, in finalize_response
    assert isinstance(response, HttpResponseBase), (
AssertionError: Expected a `Response`, `HttpResponse` or `HttpStreamingResponse` to be returned from the view, but received a `<class 'NoneType'>`
"POST /api/v1/cartlist/ HTTP/1.1" 500 80177
Internal Server Error: /api/v1/cartlist/4/
Traceback (most recent call last):
  File "/home/userdm/code/env_pool/env_gh_ht21/lib/python3.11/site-packages/django/core/handlers/exception.py", line 55, in inner
    response = get_response(request)
               ^^^^^^^^^^^^^^^^^^^^^
  File "/home/userdm/code/env_pool/env_gh_ht21/lib/python3.11/site-packages/django/core/handlers/base.py", line 197, in _get_response
    response = wrapped_callback(request, *callback_args, **callback_kwargs)
               ^^^^^^^^^^^^^^^^^^^^^^^^^^^^^^^^^^^^^^^^^^^^^^^^^^^^^^^^^^^^
  File "/home/userdm/code/env_pool/env_gh_ht21/lib/python3.11/site-packages/django/views/decorators/csrf.py", line 65, in _view_wrapper
    return view_func(request, *args, **kwargs)
           ^^^^^^^^^^^^^^^^^^^^^^^^^^^^^^^^^^^
  File "/home/userdm/code/env_pool/env_gh_ht21/lib/python3.11/site-packages/django/views/generic/base.py", line 104, in view
    return self.dispatch(request, *args, **kwargs)
           ^^^^^^^^^^^^^^^^^^^^^^^^^^^^^^^^^^^^^^^
  File "/home/userdm/code/env_pool/env_gh_ht21/lib/python3.11/site-packages/rest_framework/views.py", line 511, in dispatch
    self.response = self.finalize_response(request, response, *args, **kwargs)
                    ^^^^^^^^^^^^^^^^^^^^^^^^^^^^^^^^^^^^^^^^^^^^^^^^^^^^^^^^^^
  File "/home/userdm/code/env_pool/env_gh_ht21/lib/python3.11/site-packages/rest_framework/views.py", line 423, in finalize_response
    assert isinstance(response, HttpResponseBase), (
AssertionError: Expected a `Response`, `HttpResponse` or `HttpStreamingResponse` to be returned from the view, but received a `<class 'NoneType'>`
"POST /api/v1/cartlist/4/ HTTP/1.1" 500 80290
Internal Server Error: /api/v1/cartlist/
Traceback (most recent call last):
  File "/home/userdm/code/env_pool/env_gh_ht21/lib/python3.11/site-packages/django/core/handlers/exception.py", line 55, in inner
    response = get_response(request)
               ^^^^^^^^^^^^^^^^^^^^^
  File "/home/userdm/code/env_pool/env_gh_ht21/lib/python3.11/site-packages/django/core/handlers/base.py", line 197, in _get_response
    response = wrapped_callback(request, *callback_args, **callback_kwargs)
               ^^^^^^^^^^^^^^^^^^^^^^^^^^^^^^^^^^^^^^^^^^^^^^^^^^^^^^^^^^^^
  File "/home/userdm/code/env_pool/env_gh_ht21/lib/python3.11/site-packages/django/views/decorators/csrf.py", line 65, in _view_wrapper
    return view_func(request, *args, **kwargs)
           ^^^^^^^^^^^^^^^^^^^^^^^^^^^^^^^^^^^
  File "/home/userdm/code/env_pool/env_gh_ht21/lib/python3.11/site-packages/django/views/generic/base.py", line 104, in view
    return self.dispatch(request, *args, **kwargs)
           ^^^^^^^^^^^^^^^^^^^^^^^^^^^^^^^^^^^^^^^
  File "/home/userdm/code/env_pool/env_gh_ht21/lib/python3.11/site-packages/rest_framework/views.py", line 509, in dispatch
    response = self.handle_exception(exc)
               ^^^^^^^^^^^^^^^^^^^^^^^^^^
  File "/home/userdm/code/env_pool/env_gh_ht21/lib/python3.11/site-packages/rest_framework/views.py", line 469, in handle_exception
    self.raise_uncaught_exception(exc)
  File "/home/userdm/code/env_pool/env_gh_ht21/lib/python3.11/site-packages/rest_framework/views.py", line 480, in raise_uncaught_exception
    raise exc
  File "/home/userdm/code/env_pool/env_gh_ht21/lib/python3.11/site-packages/rest_framework/views.py", line 506, in dispatch
    response = handler(request, *args, **kwargs)
               ^^^^^^^^^^^^^^^^^^^^^^^^^^^^^^^^^
  File "/home/userdm/code/python-course/gh-hometask/HT_21/api/views.py", line 53, in post
    print(product_quantity)
          ^^^^^^^^^^^^^^^^
NameError: name 'product_quantity' is not defined
"POST /api/v1/cartlist/ HTTP/1.1" 500 95214
Internal Server Error: /api/v1/cartlist/
Traceback (most recent call last):
  File "/home/userdm/code/env_pool/env_gh_ht21/lib/python3.11/site-packages/django/core/handlers/exception.py", line 55, in inner
    response = get_response(request)
               ^^^^^^^^^^^^^^^^^^^^^
  File "/home/userdm/code/env_pool/env_gh_ht21/lib/python3.11/site-packages/django/core/handlers/base.py", line 197, in _get_response
    response = wrapped_callback(request, *callback_args, **callback_kwargs)
               ^^^^^^^^^^^^^^^^^^^^^^^^^^^^^^^^^^^^^^^^^^^^^^^^^^^^^^^^^^^^
  File "/home/userdm/code/env_pool/env_gh_ht21/lib/python3.11/site-packages/django/views/decorators/csrf.py", line 65, in _view_wrapper
    return view_func(request, *args, **kwargs)
           ^^^^^^^^^^^^^^^^^^^^^^^^^^^^^^^^^^^
  File "/home/userdm/code/env_pool/env_gh_ht21/lib/python3.11/site-packages/django/views/generic/base.py", line 104, in view
    return self.dispatch(request, *args, **kwargs)
           ^^^^^^^^^^^^^^^^^^^^^^^^^^^^^^^^^^^^^^^
  File "/home/userdm/code/env_pool/env_gh_ht21/lib/python3.11/site-packages/rest_framework/views.py", line 509, in dispatch
    response = self.handle_exception(exc)
               ^^^^^^^^^^^^^^^^^^^^^^^^^^
  File "/home/userdm/code/env_pool/env_gh_ht21/lib/python3.11/site-packages/rest_framework/views.py", line 469, in handle_exception
    self.raise_uncaught_exception(exc)
  File "/home/userdm/code/env_pool/env_gh_ht21/lib/python3.11/site-packages/rest_framework/views.py", line 480, in raise_uncaught_exception
    raise exc
  File "/home/userdm/code/env_pool/env_gh_ht21/lib/python3.11/site-packages/rest_framework/views.py", line 506, in dispatch
    response = handler(request, *args, **kwargs)
               ^^^^^^^^^^^^^^^^^^^^^^^^^^^^^^^^^
  File "/home/userdm/code/python-course/gh-hometask/HT_21/api/views.py", line 54, in post
    return Response({"error": "Invalid product id"}, status=status.HTTP_400_BAD_REQUEST)
                                                            ^^^^^^
NameError: name 'status' is not defined
"POST /api/v1/cartlist/ HTTP/1.1" 500 95837
Internal Server Error: /api/v1/cartlist/
Traceback (most recent call last):
  File "/home/userdm/code/env_pool/env_gh_ht21/lib/python3.11/site-packages/django/core/handlers/exception.py", line 55, in inner
    response = get_response(request)
               ^^^^^^^^^^^^^^^^^^^^^
  File "/home/userdm/code/env_pool/env_gh_ht21/lib/python3.11/site-packages/django/core/handlers/base.py", line 220, in _get_response
    response = response.render()
               ^^^^^^^^^^^^^^^^^
  File "/home/userdm/code/env_pool/env_gh_ht21/lib/python3.11/site-packages/django/template/response.py", line 114, in render
    self.content = self.rendered_content
                   ^^^^^^^^^^^^^^^^^^^^^
  File "/home/userdm/code/env_pool/env_gh_ht21/lib/python3.11/site-packages/rest_framework/response.py", line 70, in rendered_content
    ret = renderer.render(self.data, accepted_media_type, context)
          ^^^^^^^^^^^^^^^^^^^^^^^^^^^^^^^^^^^^^^^^^^^^^^^^^^^^^^^^
  File "/home/userdm/code/env_pool/env_gh_ht21/lib/python3.11/site-packages/rest_framework/renderers.py", line 723, in render
    context = self.get_context(data, accepted_media_type, renderer_context)
              ^^^^^^^^^^^^^^^^^^^^^^^^^^^^^^^^^^^^^^^^^^^^^^^^^^^^^^^^^^^^^
  File "/home/userdm/code/env_pool/env_gh_ht21/lib/python3.11/site-packages/rest_framework/renderers.py", line 654, in get_context
    raw_data_post_form = self.get_raw_data_form(data, view, 'POST', request)
                         ^^^^^^^^^^^^^^^^^^^^^^^^^^^^^^^^^^^^^^^^^^^^^^^^^^^
  File "/home/userdm/code/env_pool/env_gh_ht21/lib/python3.11/site-packages/rest_framework/renderers.py", line 540, in get_raw_data_form
    if not self.show_form_for_method(view, method, request, instance):
           ^^^^^^^^^^^^^^^^^^^^^^^^^^^^^^^^^^^^^^^^^^^^^^^^^^^^^^^^^^
  File "/home/userdm/code/env_pool/env_gh_ht21/lib/python3.11/site-packages/rest_framework/renderers.py", line 430, in show_form_for_method
    view.check_permissions(request)
  File "/home/userdm/code/env_pool/env_gh_ht21/lib/python3.11/site-packages/rest_framework/views.py", line 332, in check_permissions
    if not permission.has_permission(request, self):
           ^^^^^^^^^^^^^^^^^^^^^^^^^^^^^^^^^^^^^^^^
  File "/home/userdm/code/python-course/gh-hometask/HT_21/api/permission.py", line 15, in has_permission
    return request.user and request.user.request.user.is_authenticated
                            ^^^^^^^^^^^^^^^^^^^^
AttributeError: 'AnonymousUser' object has no attribute 'request'
"GET /api/v1/cartlist/ HTTP/1.1" 500 98920
Internal Server Error: /api/v1/cartlist/
Traceback (most recent call last):
  File "/home/userdm/code/env_pool/env_gh_ht21/lib/python3.11/site-packages/django/core/handlers/exception.py", line 55, in inner
    response = get_response(request)
               ^^^^^^^^^^^^^^^^^^^^^
  File "/home/userdm/code/env_pool/env_gh_ht21/lib/python3.11/site-packages/django/core/handlers/base.py", line 220, in _get_response
    response = response.render()
               ^^^^^^^^^^^^^^^^^
  File "/home/userdm/code/env_pool/env_gh_ht21/lib/python3.11/site-packages/django/template/response.py", line 114, in render
    self.content = self.rendered_content
                   ^^^^^^^^^^^^^^^^^^^^^
  File "/home/userdm/code/env_pool/env_gh_ht21/lib/python3.11/site-packages/rest_framework/response.py", line 70, in rendered_content
    ret = renderer.render(self.data, accepted_media_type, context)
          ^^^^^^^^^^^^^^^^^^^^^^^^^^^^^^^^^^^^^^^^^^^^^^^^^^^^^^^^
  File "/home/userdm/code/env_pool/env_gh_ht21/lib/python3.11/site-packages/rest_framework/renderers.py", line 723, in render
    context = self.get_context(data, accepted_media_type, renderer_context)
              ^^^^^^^^^^^^^^^^^^^^^^^^^^^^^^^^^^^^^^^^^^^^^^^^^^^^^^^^^^^^^
  File "/home/userdm/code/env_pool/env_gh_ht21/lib/python3.11/site-packages/rest_framework/renderers.py", line 654, in get_context
    raw_data_post_form = self.get_raw_data_form(data, view, 'POST', request)
                         ^^^^^^^^^^^^^^^^^^^^^^^^^^^^^^^^^^^^^^^^^^^^^^^^^^^
  File "/home/userdm/code/env_pool/env_gh_ht21/lib/python3.11/site-packages/rest_framework/renderers.py", line 540, in get_raw_data_form
    if not self.show_form_for_method(view, method, request, instance):
           ^^^^^^^^^^^^^^^^^^^^^^^^^^^^^^^^^^^^^^^^^^^^^^^^^^^^^^^^^^
  File "/home/userdm/code/env_pool/env_gh_ht21/lib/python3.11/site-packages/rest_framework/renderers.py", line 430, in show_form_for_method
    view.check_permissions(request)
  File "/home/userdm/code/env_pool/env_gh_ht21/lib/python3.11/site-packages/rest_framework/views.py", line 332, in check_permissions
    if not permission.has_permission(request, self):
           ^^^^^^^^^^^^^^^^^^^^^^^^^^^^^^^^^^^^^^^^
  File "/home/userdm/code/python-course/gh-hometask/HT_21/api/permission.py", line 15, in has_permission
    return request.user and request.user.request.user.is_authenticated
                            ^^^^^^^^^^^^^^^^^^^^
AttributeError: 'AnonymousUser' object has no attribute 'request'
"GET /api/v1/cartlist/ HTTP/1.1" 500 99057
Internal Server Error: /api/v1/cartlist/
Traceback (most recent call last):
  File "/home/userdm/code/env_pool/env_gh_ht21/lib/python3.11/site-packages/django/core/handlers/exception.py", line 55, in inner
    response = get_response(request)
               ^^^^^^^^^^^^^^^^^^^^^
  File "/home/userdm/code/env_pool/env_gh_ht21/lib/python3.11/site-packages/django/core/handlers/base.py", line 220, in _get_response
    response = response.render()
               ^^^^^^^^^^^^^^^^^
  File "/home/userdm/code/env_pool/env_gh_ht21/lib/python3.11/site-packages/django/template/response.py", line 114, in render
    self.content = self.rendered_content
                   ^^^^^^^^^^^^^^^^^^^^^
  File "/home/userdm/code/env_pool/env_gh_ht21/lib/python3.11/site-packages/rest_framework/response.py", line 70, in rendered_content
    ret = renderer.render(self.data, accepted_media_type, context)
          ^^^^^^^^^^^^^^^^^^^^^^^^^^^^^^^^^^^^^^^^^^^^^^^^^^^^^^^^
  File "/home/userdm/code/env_pool/env_gh_ht21/lib/python3.11/site-packages/rest_framework/renderers.py", line 723, in render
    context = self.get_context(data, accepted_media_type, renderer_context)
              ^^^^^^^^^^^^^^^^^^^^^^^^^^^^^^^^^^^^^^^^^^^^^^^^^^^^^^^^^^^^^
  File "/home/userdm/code/env_pool/env_gh_ht21/lib/python3.11/site-packages/rest_framework/renderers.py", line 654, in get_context
    raw_data_post_form = self.get_raw_data_form(data, view, 'POST', request)
                         ^^^^^^^^^^^^^^^^^^^^^^^^^^^^^^^^^^^^^^^^^^^^^^^^^^^
  File "/home/userdm/code/env_pool/env_gh_ht21/lib/python3.11/site-packages/rest_framework/renderers.py", line 540, in get_raw_data_form
    if not self.show_form_for_method(view, method, request, instance):
           ^^^^^^^^^^^^^^^^^^^^^^^^^^^^^^^^^^^^^^^^^^^^^^^^^^^^^^^^^^
  File "/home/userdm/code/env_pool/env_gh_ht21/lib/python3.11/site-packages/rest_framework/renderers.py", line 430, in show_form_for_method
    view.check_permissions(request)
  File "/home/userdm/code/env_pool/env_gh_ht21/lib/python3.11/site-packages/rest_framework/views.py", line 332, in check_permissions
    if not permission.has_permission(request, self):
           ^^^^^^^^^^^^^^^^^^^^^^^^^^^^^^^^^^^^^^^^
  File "/home/userdm/code/python-course/gh-hometask/HT_21/api/permission.py", line 15, in has_permission
    return request.user and request.user.request.user.is_authenticated
                            ^^^^^^^^^^^^^^^^^^^^
  File "/home/userdm/code/env_pool/env_gh_ht21/lib/python3.11/site-packages/django/utils/functional.py", line 253, in inner
    return func(_wrapped, *args)
           ^^^^^^^^^^^^^^^^^^^^^
AttributeError: 'CustomUser' object has no attribute 'request'
"GET /api/v1/cartlist/ HTTP/1.1" 500 103126
Internal Server Error: /api/v1/cartlist/
Traceback (most recent call last):
  File "/home/userdm/code/env_pool/env_gh_ht21/lib/python3.11/site-packages/django/core/handlers/exception.py", line 55, in inner
    response = get_response(request)
               ^^^^^^^^^^^^^^^^^^^^^
  File "/home/userdm/code/env_pool/env_gh_ht21/lib/python3.11/site-packages/django/core/handlers/base.py", line 220, in _get_response
    response = response.render()
               ^^^^^^^^^^^^^^^^^
  File "/home/userdm/code/env_pool/env_gh_ht21/lib/python3.11/site-packages/django/template/response.py", line 114, in render
    self.content = self.rendered_content
                   ^^^^^^^^^^^^^^^^^^^^^
  File "/home/userdm/code/env_pool/env_gh_ht21/lib/python3.11/site-packages/rest_framework/response.py", line 70, in rendered_content
    ret = renderer.render(self.data, accepted_media_type, context)
          ^^^^^^^^^^^^^^^^^^^^^^^^^^^^^^^^^^^^^^^^^^^^^^^^^^^^^^^^
  File "/home/userdm/code/env_pool/env_gh_ht21/lib/python3.11/site-packages/rest_framework/renderers.py", line 723, in render
    context = self.get_context(data, accepted_media_type, renderer_context)
              ^^^^^^^^^^^^^^^^^^^^^^^^^^^^^^^^^^^^^^^^^^^^^^^^^^^^^^^^^^^^^
  File "/home/userdm/code/env_pool/env_gh_ht21/lib/python3.11/site-packages/rest_framework/renderers.py", line 654, in get_context
    raw_data_post_form = self.get_raw_data_form(data, view, 'POST', request)
                         ^^^^^^^^^^^^^^^^^^^^^^^^^^^^^^^^^^^^^^^^^^^^^^^^^^^
  File "/home/userdm/code/env_pool/env_gh_ht21/lib/python3.11/site-packages/rest_framework/renderers.py", line 540, in get_raw_data_form
    if not self.show_form_for_method(view, method, request, instance):
           ^^^^^^^^^^^^^^^^^^^^^^^^^^^^^^^^^^^^^^^^^^^^^^^^^^^^^^^^^^
  File "/home/userdm/code/env_pool/env_gh_ht21/lib/python3.11/site-packages/rest_framework/renderers.py", line 430, in show_form_for_method
    view.check_permissions(request)
  File "/home/userdm/code/env_pool/env_gh_ht21/lib/python3.11/site-packages/rest_framework/views.py", line 332, in check_permissions
    if not permission.has_permission(request, self):
           ^^^^^^^^^^^^^^^^^^^^^^^^^^^^^^^^^^^^^^^^
  File "/home/userdm/code/python-course/gh-hometask/HT_21/api/permission.py", line 15, in has_permission
    return request.user and request.user.request.user.is_authenticated
                            ^^^^^^^^^^^^^^^^^^^^
  File "/home/userdm/code/env_pool/env_gh_ht21/lib/python3.11/site-packages/django/utils/functional.py", line 253, in inner
    return func(_wrapped, *args)
           ^^^^^^^^^^^^^^^^^^^^^
AttributeError: 'CustomUser' object has no attribute 'request'
"GET /api/v1/cartlist/ HTTP/1.1" 500 103263
Internal Server Error: /api/v1/cartlist/
Traceback (most recent call last):
  File "/home/userdm/code/env_pool/env_gh_ht21/lib/python3.11/site-packages/django/core/handlers/exception.py", line 55, in inner
    response = get_response(request)
               ^^^^^^^^^^^^^^^^^^^^^
  File "/home/userdm/code/env_pool/env_gh_ht21/lib/python3.11/site-packages/django/core/handlers/base.py", line 220, in _get_response
    response = response.render()
               ^^^^^^^^^^^^^^^^^
  File "/home/userdm/code/env_pool/env_gh_ht21/lib/python3.11/site-packages/django/template/response.py", line 114, in render
    self.content = self.rendered_content
                   ^^^^^^^^^^^^^^^^^^^^^
  File "/home/userdm/code/env_pool/env_gh_ht21/lib/python3.11/site-packages/rest_framework/response.py", line 70, in rendered_content
    ret = renderer.render(self.data, accepted_media_type, context)
          ^^^^^^^^^^^^^^^^^^^^^^^^^^^^^^^^^^^^^^^^^^^^^^^^^^^^^^^^
  File "/home/userdm/code/env_pool/env_gh_ht21/lib/python3.11/site-packages/rest_framework/renderers.py", line 723, in render
    context = self.get_context(data, accepted_media_type, renderer_context)
              ^^^^^^^^^^^^^^^^^^^^^^^^^^^^^^^^^^^^^^^^^^^^^^^^^^^^^^^^^^^^^
  File "/home/userdm/code/env_pool/env_gh_ht21/lib/python3.11/site-packages/rest_framework/renderers.py", line 654, in get_context
    raw_data_post_form = self.get_raw_data_form(data, view, 'POST', request)
                         ^^^^^^^^^^^^^^^^^^^^^^^^^^^^^^^^^^^^^^^^^^^^^^^^^^^
  File "/home/userdm/code/env_pool/env_gh_ht21/lib/python3.11/site-packages/rest_framework/renderers.py", line 540, in get_raw_data_form
    if not self.show_form_for_method(view, method, request, instance):
           ^^^^^^^^^^^^^^^^^^^^^^^^^^^^^^^^^^^^^^^^^^^^^^^^^^^^^^^^^^
  File "/home/userdm/code/env_pool/env_gh_ht21/lib/python3.11/site-packages/rest_framework/renderers.py", line 430, in show_form_for_method
    view.check_permissions(request)
  File "/home/userdm/code/env_pool/env_gh_ht21/lib/python3.11/site-packages/rest_framework/views.py", line 332, in check_permissions
    if not permission.has_permission(request, self):
           ^^^^^^^^^^^^^^^^^^^^^^^^^^^^^^^^^^^^^^^^
  File "/home/userdm/code/python-course/gh-hometask/HT_21/api/permission.py", line 15, in has_permission
    return request.user and request.user.request.user.is_authenticated
                            ^^^^^^^^^^^^^^^^^^^^
  File "/home/userdm/code/env_pool/env_gh_ht21/lib/python3.11/site-packages/django/utils/functional.py", line 253, in inner
    return func(_wrapped, *args)
           ^^^^^^^^^^^^^^^^^^^^^
AttributeError: 'CustomUser' object has no attribute 'request'
"GET /api/v1/cartlist/ HTTP/1.1" 500 103659
Internal Server Error: /api/v1/cartlist/
Traceback (most recent call last):
  File "/home/userdm/code/env_pool/env_gh_ht21/lib/python3.11/site-packages/django/core/handlers/exception.py", line 55, in inner
    response = get_response(request)
               ^^^^^^^^^^^^^^^^^^^^^
  File "/home/userdm/code/env_pool/env_gh_ht21/lib/python3.11/site-packages/django/core/handlers/base.py", line 220, in _get_response
    response = response.render()
               ^^^^^^^^^^^^^^^^^
  File "/home/userdm/code/env_pool/env_gh_ht21/lib/python3.11/site-packages/django/template/response.py", line 114, in render
    self.content = self.rendered_content
                   ^^^^^^^^^^^^^^^^^^^^^
  File "/home/userdm/code/env_pool/env_gh_ht21/lib/python3.11/site-packages/rest_framework/response.py", line 70, in rendered_content
    ret = renderer.render(self.data, accepted_media_type, context)
          ^^^^^^^^^^^^^^^^^^^^^^^^^^^^^^^^^^^^^^^^^^^^^^^^^^^^^^^^
  File "/home/userdm/code/env_pool/env_gh_ht21/lib/python3.11/site-packages/rest_framework/renderers.py", line 723, in render
    context = self.get_context(data, accepted_media_type, renderer_context)
              ^^^^^^^^^^^^^^^^^^^^^^^^^^^^^^^^^^^^^^^^^^^^^^^^^^^^^^^^^^^^^
  File "/home/userdm/code/env_pool/env_gh_ht21/lib/python3.11/site-packages/rest_framework/renderers.py", line 654, in get_context
    raw_data_post_form = self.get_raw_data_form(data, view, 'POST', request)
                         ^^^^^^^^^^^^^^^^^^^^^^^^^^^^^^^^^^^^^^^^^^^^^^^^^^^
  File "/home/userdm/code/env_pool/env_gh_ht21/lib/python3.11/site-packages/rest_framework/renderers.py", line 540, in get_raw_data_form
    if not self.show_form_for_method(view, method, request, instance):
           ^^^^^^^^^^^^^^^^^^^^^^^^^^^^^^^^^^^^^^^^^^^^^^^^^^^^^^^^^^
  File "/home/userdm/code/env_pool/env_gh_ht21/lib/python3.11/site-packages/rest_framework/renderers.py", line 430, in show_form_for_method
    view.check_permissions(request)
  File "/home/userdm/code/env_pool/env_gh_ht21/lib/python3.11/site-packages/rest_framework/views.py", line 332, in check_permissions
    if not permission.has_permission(request, self):
           ^^^^^^^^^^^^^^^^^^^^^^^^^^^^^^^^^^^^^^^^
  File "/home/userdm/code/python-course/gh-hometask/HT_21/api/permission.py", line 15, in has_permission
    return request.user and request.user.request.user.is_authenticated
                            ^^^^^^^^^^^^^^^^^^^^
  File "/home/userdm/code/env_pool/env_gh_ht21/lib/python3.11/site-packages/django/utils/functional.py", line 253, in inner
    return func(_wrapped, *args)
           ^^^^^^^^^^^^^^^^^^^^^
AttributeError: 'CustomUser' object has no attribute 'request'
"GET /api/v1/cartlist/ HTTP/1.1" 500 103796
Internal Server Error: /api/v1/cartlist/
Traceback (most recent call last):
  File "/home/userdm/code/env_pool/env_gh_ht21/lib/python3.11/site-packages/django/core/handlers/exception.py", line 55, in inner
    response = get_response(request)
               ^^^^^^^^^^^^^^^^^^^^^
  File "/home/userdm/code/env_pool/env_gh_ht21/lib/python3.11/site-packages/django/core/handlers/base.py", line 220, in _get_response
    response = response.render()
               ^^^^^^^^^^^^^^^^^
  File "/home/userdm/code/env_pool/env_gh_ht21/lib/python3.11/site-packages/django/template/response.py", line 114, in render
    self.content = self.rendered_content
                   ^^^^^^^^^^^^^^^^^^^^^
  File "/home/userdm/code/env_pool/env_gh_ht21/lib/python3.11/site-packages/rest_framework/response.py", line 70, in rendered_content
    ret = renderer.render(self.data, accepted_media_type, context)
          ^^^^^^^^^^^^^^^^^^^^^^^^^^^^^^^^^^^^^^^^^^^^^^^^^^^^^^^^
  File "/home/userdm/code/env_pool/env_gh_ht21/lib/python3.11/site-packages/rest_framework/renderers.py", line 723, in render
    context = self.get_context(data, accepted_media_type, renderer_context)
              ^^^^^^^^^^^^^^^^^^^^^^^^^^^^^^^^^^^^^^^^^^^^^^^^^^^^^^^^^^^^^
  File "/home/userdm/code/env_pool/env_gh_ht21/lib/python3.11/site-packages/rest_framework/renderers.py", line 654, in get_context
    raw_data_post_form = self.get_raw_data_form(data, view, 'POST', request)
                         ^^^^^^^^^^^^^^^^^^^^^^^^^^^^^^^^^^^^^^^^^^^^^^^^^^^
  File "/home/userdm/code/env_pool/env_gh_ht21/lib/python3.11/site-packages/rest_framework/renderers.py", line 540, in get_raw_data_form
    if not self.show_form_for_method(view, method, request, instance):
           ^^^^^^^^^^^^^^^^^^^^^^^^^^^^^^^^^^^^^^^^^^^^^^^^^^^^^^^^^^
  File "/home/userdm/code/env_pool/env_gh_ht21/lib/python3.11/site-packages/rest_framework/renderers.py", line 430, in show_form_for_method
    view.check_permissions(request)
  File "/home/userdm/code/env_pool/env_gh_ht21/lib/python3.11/site-packages/rest_framework/views.py", line 332, in check_permissions
    if not permission.has_permission(request, self):
           ^^^^^^^^^^^^^^^^^^^^^^^^^^^^^^^^^^^^^^^^
  File "/home/userdm/code/python-course/gh-hometask/HT_21/api/permission.py", line 15, in has_permission
    return request.user and request.user.request.user.is_authenticated
                            ^^^^^^^^^^^^^^^^^^^^
  File "/home/userdm/code/env_pool/env_gh_ht21/lib/python3.11/site-packages/django/utils/functional.py", line 253, in inner
    return func(_wrapped, *args)
           ^^^^^^^^^^^^^^^^^^^^^
AttributeError: 'CustomUser' object has no attribute 'request'
"GET /api/v1/cartlist/ HTTP/1.1" 500 103796
Internal Server Error: /api/v1/cartlist/
Traceback (most recent call last):
  File "/home/userdm/code/env_pool/env_gh_ht21/lib/python3.11/site-packages/django/core/handlers/exception.py", line 55, in inner
    response = get_response(request)
               ^^^^^^^^^^^^^^^^^^^^^
  File "/home/userdm/code/env_pool/env_gh_ht21/lib/python3.11/site-packages/django/core/handlers/base.py", line 220, in _get_response
    response = response.render()
               ^^^^^^^^^^^^^^^^^
  File "/home/userdm/code/env_pool/env_gh_ht21/lib/python3.11/site-packages/django/template/response.py", line 114, in render
    self.content = self.rendered_content
                   ^^^^^^^^^^^^^^^^^^^^^
  File "/home/userdm/code/env_pool/env_gh_ht21/lib/python3.11/site-packages/rest_framework/response.py", line 70, in rendered_content
    ret = renderer.render(self.data, accepted_media_type, context)
          ^^^^^^^^^^^^^^^^^^^^^^^^^^^^^^^^^^^^^^^^^^^^^^^^^^^^^^^^
  File "/home/userdm/code/env_pool/env_gh_ht21/lib/python3.11/site-packages/rest_framework/renderers.py", line 723, in render
    context = self.get_context(data, accepted_media_type, renderer_context)
              ^^^^^^^^^^^^^^^^^^^^^^^^^^^^^^^^^^^^^^^^^^^^^^^^^^^^^^^^^^^^^
  File "/home/userdm/code/env_pool/env_gh_ht21/lib/python3.11/site-packages/rest_framework/renderers.py", line 654, in get_context
    raw_data_post_form = self.get_raw_data_form(data, view, 'POST', request)
                         ^^^^^^^^^^^^^^^^^^^^^^^^^^^^^^^^^^^^^^^^^^^^^^^^^^^
  File "/home/userdm/code/env_pool/env_gh_ht21/lib/python3.11/site-packages/rest_framework/renderers.py", line 540, in get_raw_data_form
    if not self.show_form_for_method(view, method, request, instance):
           ^^^^^^^^^^^^^^^^^^^^^^^^^^^^^^^^^^^^^^^^^^^^^^^^^^^^^^^^^^
  File "/home/userdm/code/env_pool/env_gh_ht21/lib/python3.11/site-packages/rest_framework/renderers.py", line 430, in show_form_for_method
    view.check_permissions(request)
  File "/home/userdm/code/env_pool/env_gh_ht21/lib/python3.11/site-packages/rest_framework/views.py", line 332, in check_permissions
    if not permission.has_permission(request, self):
           ^^^^^^^^^^^^^^^^^^^^^^^^^^^^^^^^^^^^^^^^
  File "/home/userdm/code/python-course/gh-hometask/HT_21/api/permission.py", line 15, in has_permission
    return request.user and request.user.request.user.is_authenticated
                            ^^^^^^^^^^^^^^^^^^^^
  File "/home/userdm/code/env_pool/env_gh_ht21/lib/python3.11/site-packages/django/utils/functional.py", line 253, in inner
    return func(_wrapped, *args)
           ^^^^^^^^^^^^^^^^^^^^^
AttributeError: 'CustomUser' object has no attribute 'request'
"GET /api/v1/cartlist/ HTTP/1.1" 500 103796
Internal Server Error: /api/v1/cartlist/
Traceback (most recent call last):
  File "/home/userdm/code/env_pool/env_gh_ht21/lib/python3.11/site-packages/django/core/handlers/exception.py", line 55, in inner
    response = get_response(request)
               ^^^^^^^^^^^^^^^^^^^^^
  File "/home/userdm/code/env_pool/env_gh_ht21/lib/python3.11/site-packages/django/core/handlers/base.py", line 220, in _get_response
    response = response.render()
               ^^^^^^^^^^^^^^^^^
  File "/home/userdm/code/env_pool/env_gh_ht21/lib/python3.11/site-packages/django/template/response.py", line 114, in render
    self.content = self.rendered_content
                   ^^^^^^^^^^^^^^^^^^^^^
  File "/home/userdm/code/env_pool/env_gh_ht21/lib/python3.11/site-packages/rest_framework/response.py", line 70, in rendered_content
    ret = renderer.render(self.data, accepted_media_type, context)
          ^^^^^^^^^^^^^^^^^^^^^^^^^^^^^^^^^^^^^^^^^^^^^^^^^^^^^^^^
  File "/home/userdm/code/env_pool/env_gh_ht21/lib/python3.11/site-packages/rest_framework/renderers.py", line 723, in render
    context = self.get_context(data, accepted_media_type, renderer_context)
              ^^^^^^^^^^^^^^^^^^^^^^^^^^^^^^^^^^^^^^^^^^^^^^^^^^^^^^^^^^^^^
  File "/home/userdm/code/env_pool/env_gh_ht21/lib/python3.11/site-packages/rest_framework/renderers.py", line 654, in get_context
    raw_data_post_form = self.get_raw_data_form(data, view, 'POST', request)
                         ^^^^^^^^^^^^^^^^^^^^^^^^^^^^^^^^^^^^^^^^^^^^^^^^^^^
  File "/home/userdm/code/env_pool/env_gh_ht21/lib/python3.11/site-packages/rest_framework/renderers.py", line 540, in get_raw_data_form
    if not self.show_form_for_method(view, method, request, instance):
           ^^^^^^^^^^^^^^^^^^^^^^^^^^^^^^^^^^^^^^^^^^^^^^^^^^^^^^^^^^
  File "/home/userdm/code/env_pool/env_gh_ht21/lib/python3.11/site-packages/rest_framework/renderers.py", line 430, in show_form_for_method
    view.check_permissions(request)
  File "/home/userdm/code/env_pool/env_gh_ht21/lib/python3.11/site-packages/rest_framework/views.py", line 332, in check_permissions
    if not permission.has_permission(request, self):
           ^^^^^^^^^^^^^^^^^^^^^^^^^^^^^^^^^^^^^^^^
  File "/home/userdm/code/python-course/gh-hometask/HT_21/api/permission.py", line 15, in has_permission
    return request.user and request.user.request.user.is_authenticated
                            ^^^^^^^^^^^^^^^^^^^^
  File "/home/userdm/code/env_pool/env_gh_ht21/lib/python3.11/site-packages/django/utils/functional.py", line 253, in inner
    return func(_wrapped, *args)
           ^^^^^^^^^^^^^^^^^^^^^
AttributeError: 'CustomUser' object has no attribute 'request'
"GET /api/v1/cartlist/ HTTP/1.1" 500 103796
Internal Server Error: /api/v1/cartlist/
Traceback (most recent call last):
  File "/home/userdm/code/env_pool/env_gh_ht21/lib/python3.11/site-packages/django/core/handlers/exception.py", line 55, in inner
    response = get_response(request)
               ^^^^^^^^^^^^^^^^^^^^^
  File "/home/userdm/code/env_pool/env_gh_ht21/lib/python3.11/site-packages/django/core/handlers/base.py", line 220, in _get_response
    response = response.render()
               ^^^^^^^^^^^^^^^^^
  File "/home/userdm/code/env_pool/env_gh_ht21/lib/python3.11/site-packages/django/template/response.py", line 114, in render
    self.content = self.rendered_content
                   ^^^^^^^^^^^^^^^^^^^^^
  File "/home/userdm/code/env_pool/env_gh_ht21/lib/python3.11/site-packages/rest_framework/response.py", line 70, in rendered_content
    ret = renderer.render(self.data, accepted_media_type, context)
          ^^^^^^^^^^^^^^^^^^^^^^^^^^^^^^^^^^^^^^^^^^^^^^^^^^^^^^^^
  File "/home/userdm/code/env_pool/env_gh_ht21/lib/python3.11/site-packages/rest_framework/renderers.py", line 723, in render
    context = self.get_context(data, accepted_media_type, renderer_context)
              ^^^^^^^^^^^^^^^^^^^^^^^^^^^^^^^^^^^^^^^^^^^^^^^^^^^^^^^^^^^^^
  File "/home/userdm/code/env_pool/env_gh_ht21/lib/python3.11/site-packages/rest_framework/renderers.py", line 654, in get_context
    raw_data_post_form = self.get_raw_data_form(data, view, 'POST', request)
                         ^^^^^^^^^^^^^^^^^^^^^^^^^^^^^^^^^^^^^^^^^^^^^^^^^^^
  File "/home/userdm/code/env_pool/env_gh_ht21/lib/python3.11/site-packages/rest_framework/renderers.py", line 540, in get_raw_data_form
    if not self.show_form_for_method(view, method, request, instance):
           ^^^^^^^^^^^^^^^^^^^^^^^^^^^^^^^^^^^^^^^^^^^^^^^^^^^^^^^^^^
  File "/home/userdm/code/env_pool/env_gh_ht21/lib/python3.11/site-packages/rest_framework/renderers.py", line 430, in show_form_for_method
    view.check_permissions(request)
  File "/home/userdm/code/env_pool/env_gh_ht21/lib/python3.11/site-packages/rest_framework/views.py", line 332, in check_permissions
    if not permission.has_permission(request, self):
           ^^^^^^^^^^^^^^^^^^^^^^^^^^^^^^^^^^^^^^^^
  File "/home/userdm/code/python-course/gh-hometask/HT_21/api/permission.py", line 15, in has_permission
    return request.user and request.user.request.user.is_authenticated
                            ^^^^^^^^^^^^^^^^^^^^
  File "/home/userdm/code/env_pool/env_gh_ht21/lib/python3.11/site-packages/django/utils/functional.py", line 253, in inner
    return func(_wrapped, *args)
           ^^^^^^^^^^^^^^^^^^^^^
AttributeError: 'CustomUser' object has no attribute 'request'
"GET /api/v1/cartlist/ HTTP/1.1" 500 103659
